Workbook

Sheet 00_整合说明
A1: 以人为中心的全双工多模态交互世界模型：数据执行仪表盘
A2: 知识库保留完整字段；日常推进优先使用「01A_执行决策视图」「05_下载申请清单」「13_访问状态审计」。
A4: 主表条目 | E4: 执行清单 P0 | I4: A 类直接获取 | M4: C 类人工申请 | Q4: 遗漏候选
A5: 90 | E5: 8 | M5: 14 | Q5: 15
A8: 推荐首期方案 | E8: 两周 Smoke Set | M8: 优先补充 P0 | Q8: 执行视图字段
A9: 118 小时 | E9: 40 小时 | M9: 3 项 | Q9: 22 列
A12: 访问状态分布 | N12: P0 / P1 本周行动
A13: 等级 | B13: 条目数 | C13: 能否立即开始 | N13: 优先级 | O13: 数据 | P13: 访问 | Q13: 立即动作 | U13: 日程
A14: A 直接下载/安装 | B14: =COUNTIF('13_访问状态审计'!$R$2:$R$200,"A") | C14: 是 | N14: P0 | O14: HoloAssist | P14: A | Q14: 下载1–2个session | U14: Day1–2
A15: B 注册/接受条款 | B15: =COUNTIF('13_访问状态审计'!$R$2:$R$200,"B") | C15: 通常可以 | N15: P0 | O15: MIRA | P15: B | Q15: 接受条款，下载test | U15: Day1–2
A16: C 申请/人工审批 | B16: =COUNTIF('13_访问状态审计'!$R$2:$R$200,"C") | C16: 否 | N16: P0 | O16: EPIC-KITCHENS | P16: A | Q16: annotations + 原始视频pilot | U16: Day1–3
A17: D 仅索引/自行抓取 | B17: =COUNTIF('13_访问状态审计'!$R$2:$R$200,"D") | C17: 否 | N17: P0 | O17: Ego4D | P17: C | Q17: 提交许可申请 | U17: Day1
A18: E 未开放/待核验 | B18: =COUNTIF('13_访问状态审计'!$R$2:$R$200,"E") | C18: 否 | D18: 只跟踪，不承诺小时 | N18: P0 | O18: ViCo / EasyCom | P18: A | Q18: 下载全量或1个session | U18: Day1–3
A19: F 部分可得/依赖上游 | B19: =COUNTIF('13_访问状态审计'!$R$2:$R$200,"F") | C19: 部分 | D19: 逐子集审计 | N19: P0 | O19: AgiBot World | P19: B | Q19: 接受条款，下载小分片 | U19: Day1–4
N20: P1 | O20: RoboCasa365 | P20: A | Q20: 生成20条状态轨迹 | U20: Day3–7
A23: 118 小时首期方案 | N23: 如何使用本工作簿
A24: 模块 | B24: 小时 | C24: 比例 | D24: 用途 | N24: 页面 | O24: 用途 | U24: 建议频率
A25: MIRA Rocket Science | B25: 20 | C25: =B25/$B$34 | D25: 动作/状态/多实体 | N25: 01A_执行决策视图 | O25: 日常筛选：优先级、访问、动作、状态 | U25: 每天
A26: EPIC-KITCHENS-100 | B26: 18 | C26: =B26/$B$34 | D26: 真实人-物状态变化 | N26: 05_下载申请清单 | O26: 下载、申请、负责人和完成标准 | U26: 每天
A27: MineRL + BEDD | B27: 20 | C27: =B27/$B$34 | D27: 键鼠动作/任务成功 | N27: 13_访问状态审计 | O27: 许可与实际可获得内容 | U27: 每周
A28: Ego4D 精选 | B28: 8 | C28: =B28/$B$34 | D28: 真实HOI/社交/记忆 | N28: 14_遗漏补充候选 | O28: 评审新增数据集是否纳入主表 | U28: 每周
A29: ViCo + EasyCom | B29: 4 | C29: =B29/$B$34 | D29: 倾听/多人AV | N29: 01_统一决策总表 | O29: 完整能力、许可、证据和评分 | U29: 需要时
A30: VirtualHome + TEACh | B30: 8 | C30: =B30/$B$34 | D30: 显式状态/对话纠错 | N30: RAW_* | O30: 来源追溯，不建议日常编辑 | U30: 审计时
A31: DROID 精选 | B31: 8 | C31: =B31/$B$34 | D31: 精确动作—结果
A32: Assembly101 精选 | B32: 8 | C32: =B32/$B$34 | D32: 装配/错误纠正 | N32: 决策底线
A33: HoloAssist + 扩展 | B33: 24 | C33: =B33/$B$34 | D33: 全双工/手物/数字人 | N33: 1 | O33: 评分不能覆盖许可与可访问性。
A34: 合计 | B34: =SUM(B25:B33) | C34: 100% | N34: 2 | O34: 论文规模不能替代实际成功下载小时。
N35: 3 | O35: VLM 标注不能覆盖日志、传感器或仿真真值。
N36: 4 | O36: 先跑通 40h smoke set，再扩展至 118h。

Sheet 01_统一决策总表
A1: 数据集名称 | B1: 来源覆盖 | C1: 数据池/类别 | D1: 子类/来源 | E1: 发布年份 | F1: 当前可用状态 | G1: 获取/申请方式 | H1: 执行优先级 | I1: 系统优先级 | J1: 深研优先级 | K1: 整合行动级别 | L1: 系统28维平均分 | M1: 深研加权分 | N1: 是否立即行动 | O1: 最小验证集 | P1: 首期目标 | Q1: 预计空间 | R1: 规模/时长 | S1: 分辨率/FPS | T1: 视角 | U1: 关键模态 | V1: 人物/身份 | W1: 音频/语音 | X1: 动作监督 | Y1: 状态监督 | Z1: 交互/多智能体 | AA1: 长时/记忆价值 | AB1: 推荐阶段 | AC1: 最适合训练能力 | AD1: 推荐使用方式 | AE1: 推荐采样时长 | AF1: 许可与限制 | AG1: 允许生成模型训练 | AH1: 许可动作 | AI1: 完成标准 | AJ1: 主要风险/质量问题 | AK1: 核心理由/评分依据 | AL1: 官方/证据链接 | AM1: 信息可信度 | AN1: 原始名称映射
A2: Assembly101 | B2: 系统+深研 | C2: D ; 多视角/人-物/装配/错误纠正 | D2: 多视角装配长任务 ; 装配/拆卸 101 种玩具车 | E2: 2022-03；2026-05 迁移至 Hugging Face | F2: 公开可下载 | G2: 官方项目 ; 下一个任务、少量视角 | H2: P0 | I2: S | J2: S | K2: P0 | L2: 2.57 | M2: 4.45 | N2: 下一个任务、少量视角 | O2: 1–2玩具/2视角 | P2: 8–12h | Q2: 0.2–0.8TB ; 较大；不宜全量多视角 | R2: 常见统计约 513 小时；需用 metadata 核验 ; 4,321 videos；12 同步视角 ; 约432小时 | T2: 8 固定 + 4 第一人称 | U2: RGB,AudioPartial,Hand,MultiView,Long ; 音频:非核心/未确认 ; 语音:否/非核心 ; 相机:有相机外参 | V2: participant ID ; 是 ; 否 | W2: 非核心/未确认 ; 否/非核心 ; 部分 | X2: 是 ; 100k+ coarse、1M fine-grained ; 多步骤、错误和纠正对状态/恢复关键 | Y2: 装配进度/错误 ; 强 ; 否 | Z2: HOI,Failure,Recovery,ActionBoundary,Episode ; 单人操作 ; 单人为主 | AA2: 长视频:是 ; 完整episode:是 ; 长上下文:是 ; 程序活动长序列 | AB2: Stage 3/6 | AC2: 装配/拆卸、失败纠正、多视角状态一致性 | AD2: 只下 1–2 视角和约 10 小时；保留错误/纠正 | AE2: 5–12 秒 | AF2: CC BY-NC 4.0 | AG2: 非商业研究可行 ; 需法务复核 | AH2: 保存CC BY-NC | AI2: 动作/手姿态/相机可解析 | AJ2: 受控玩具域、音频弱、多视角冗余 ; 装配域、存储和多视角成本 | AK2: 装配/拆卸、失败纠正、多视角状态一致性 ; 动作和状态精细，多视角成本高 ; 多步骤、错误和纠正对状态/恢复关键 | AL2: https://assembly-101.github.io ; https://github.com/assembly-101 ; https://assembly-101.github.io/ | AM2: 高（总时长字段中） | AN2: Assembly101
A3: EPIC-KITCHENS-100 | B3: 系统+深研 | C3: D ; 第一人称/厨房/人-物/音视频 | D3: 第一人称厨房HOI ; 45 个真实家庭厨房非脚本化录制 | E3: 2020/2022；2026 仍维护 | F3: 公开可下载 | G3: 官方下载工具 ; annotations + 2–5原始视频 | H3: P0 | I3: S | J3: S | K3: P0 | L3: 3.07 | M3: 4.61 | N3: annotations + 2–5原始视频 | O3: 约20GB pilot | P3: 18–30h | Q3: 0.2–0.5TB ; Extended 约 740GB zipped；Original 约 1.1TB zipped；自动标注约 10GB | R3: 100 小时 ; 约 700 长视频；约 90k action segments ; 约100小时 | S3: Full HD ; 依设备/metadata | T3: 第一人称 | U3: RGB,Audio,Text,HumanCaption,Hand,Long ; 音频:是 ; 语音:多语言 narration；场景语音不一定持续 ; 深度:否 ; 相机:部分 IMU 扩展 | V3: participant ID ; 按参与者/厨房 ; 是 ; 否 | W3: 是 ; 多语言 narration；场景语音不一定持续 | X3: 是 ; 起止时间 + verb/noun/action ; 否 ; 真实无脚本HOI、动作意图和完整episode | Y3: 动作与对象状态可推导 ; 强；开/关、切/洗/放等 ; 否 | Z3: HOI,HEI,ActionBoundary,Episode ; 单人佩戴者为主 ; 弱 ; 单人为主 | AA3: 长视频:是 ; 完整episode:是 ; 长上下文:是 ; 长序列；动作段秒级 | AB3: Stage 3/6 | AC3: 人-物状态变化、第一人称动作、环境音效 | AD3: 取 15–30 小时，按 verb/noun/state-change 均衡 | AE3: 4–8 秒；前后各留 1–2 秒 | AF3: CC BY-NC 4.0 | AG3: 非商业研究通常可行 ; 需法务复核 | AH3: 保存CC BY-NC 4.0 | AI3: 裁切/音频/before-after全链路 | AJ3: 厨房域集中、抖动、动作边界/narration 噪声 ; 厨房域和第一人称偏差 | AK3: 人-物状态变化、第一人称动作、环境音效 ; 首期最稳妥的真实状态变化数据 ; 真实无脚本HOI、动作意图和完整episode | AL3: https://epic-kitchens.github.io/2026 ; https://epic-kitchens.github.io/2026#downloads ; https://github.com/epic-kitchens ; https://epic-kitchens.github.io/ | AM3: 高 | AN3: EPIC-KITCHENS-100
A4: EasyCom | B4: 系统+深研 | C4: C ; 多人对话/第一人称/阵列音频 | D4: 多人对话多模态会议 ; 噪声环境动态多人对话，AR眼镜采集 | E4: 2021-07 | F4: 官方仓库与 Releases 可直接下载 | G4: GitHub clone / Releases 直接下载 | H4: P0 | I4: S | J4: A | K4: P0 | L4: 2.96 | M4: 3.97 | N4: 下载 1 个 session pilot | O4: 1 session | P4: 全量5h | Q4: 0.1–0.5TB ; 中小 | R4: 5+ 小时 ; 多人多通道 | T4: 第一人称AR眼镜 | U4: RGB,Audio,MultiChannel,MultiView,SpeakerID,VAD,GazePartial,Listener ; 音频:多通道阵列 + headset mic ; 语音:是 ; 相机:AR设备标定/元数据 | V4: source ID ; 是 | W4: 多通道阵列 + headset mic ; 是 | X4: 社交/语音事件 ; VAD、speech source、target listener、head boxes ; 多人、重叠、听者和多通道数据稀缺 | Y4: 对话状态 ; 否 | Z4: HHI,Overlap ; 多人 ; 目标说话对象/说话人归属 ; 多人/双人 | AA4: 长视频:否 ; 完整episode:否 ; 长上下文:部分 ; 长会话 | AB4: Stage 2/3/5 | AC4: 多人说话人归属、语音-视线-目标对齐、噪声鲁棒 | AD4: 全量用于AV对齐/评估；视频生成仅小比例 | AE4: 8–20 秒 | AF4: 官方数据条款需下载前核查 | AG4: 需确认 ; 需法务复核 | AH4: 核查协议 | AI4: 视频/阵列音频/VAD/转录可对齐 | AJ4: 时长小；视觉主要服务音频研究；人物动作范围有限 ; 会议/头戴域、隐私和协议 | AK4: 多人说话人归属、语音-视线-目标对齐、噪声鲁棒 ; 说话人归属与全双工感知强 ; 多人、重叠、听者和多通道数据稀缺 | AL4: https://arxiv.org/abs/2107.04174 ; https://github.com/facebookresearch/EasyComDataset | AM4: 中高 | AN4: EasyCom
A5: Ego4D | B5: 系统+深研 | C5: D ; 第一人称/人-物/社交/记忆/音视频 | D5: 大规模第一人称自然活动 ; 9 国、74 地点真实日常活动 | E5: 2021-10；持续更新 | F5: 可申请下载 | G5: 许可协议+AWS CLI ; 签许可并配CLI | H5: P0 | I5: S | J5: S | K5: P0 | L5: 3.04 | M5: 4.15 | N5: 签许可并配CLI | O5: HOI/Social sample | P5: 8–15h | Q5: 0.3–1TB ; 全量极大；按 annotation 子集下载 | R5: 3,670 小时 ; 923 名参与者；视频数量随版本 ; 3,670小时 | S5: 多设备异构；有标准化版 ; 标准化 30fps | T5: 第一人称 | U5: RGB,AudioPartial,Text,HumanCaption,Hand,GazePartial,DepthPartial,IMUPartial,MultiViewPartial,Long ; 音频:部分大规模视频含音频 ; 语音:是；Social/AV diarization 子集 ; 深度:部分/非全量 ; 相机:部分设备/子集 | V5: 受隐私保护/部分去标识化 ; 会话内/部分任务 ; 是 ; 否 | W5: 部分大规模视频含音频 ; 是；Social/AV diarization 子集 ; 是 ; 部分 | X5: 是 ; 动作段、未来动作、PNR、active object ; 否 ; 现实长时交互、状态前后和记忆监督全面 | Y5: Episodic Memory 与 HOI 状态 ; HOI 含 prior/posterior state 与 PNR ; 否 ; 是 | Z5: HHI,HOI,HEI,StateChange,Episode ; 佩戴者 + 社交场景多人 ; looking/talking/AV diarization ; 多人/双人 | AA5: 长视频:是 ; 完整episode:是 ; 长上下文:是 ; 分钟级长视频 | AB5: Stage 3/6 | AC5: 真实人-物状态、探索、社交/听说、长期记忆 | AD5: 取 HOI+Social+AVD+Episodic Memory 的 10–20 小时交集 | AE5: 动作 4–10 秒；对话 8–16 秒；保留长上下文索引 | AF5: Ego4D 自定义许可；需签署 | AG5: 需依据许可和机构合规解释 ; 需法务复核 | AH5: 归档协议 | AI5: 审批通过并生成manifest | AJ5: 设备异质、隐私模糊、长视频筛选成本高、无低层动作 ; 第一人称域、隐私、存储和benchmark泄漏 | AK5: 真实人-物状态、探索、社交/听说、长期记忆 ; 真实交互广，筛选/许可成本高 ; 现实长时交互、状态前后和记忆监督全面 | AL5: https://ego4d-data.org ; https://ego4d-data.org/#download ; https://github.com/facebookresearch/Ego4d ; https://ego4d-data.org/ | AM5: 高 | AN5: Ego4D
A6: MIRA Rocket Science | B6: 深研 | C6: 游戏/多智能体/动作条件 | D6: Rocket League bot 比赛；四名玩家同步视角 | E6: 2026-07 | F6: 登录 Hugging Face 并接受条款后可下载 | G6: HF 登录 + 接受条款；优先下载 test 109GB | H6: P0 | J6: A | K6: P0 | M6: 3.88 | N6: 登录并接受条款，下载 test | O6: 1 shard/test 109GB | P6: 20–35h | Q6: 0.1–0.3TB ; 全量约 29.2TB；测试集约 109GB | R6: 约 10,000 小时 ; 训练 15,769 场、约 1,792,926 个 4 秒 chunk；测试 62 场 | S6: 1280×720 H.264 ; 20 | T6: 4 个同步玩家视角 | U6: 音频:否 ; 语音:否 ; 深度:否 | V6: player_id/team；无真人身份 ; 是 | W6: 否 | X6: 是 ; 逐帧 9 维 multi-hot 键盘状态 ; W/A/S/D/Q/E/Space/Shift/Ctrl | Y6: 逐帧球、车辆、boost、比分、时钟与事件 ; 可由 physics/events 直接差分 | Z6: 4 个玩家代理 ; 队伍与对抗关系 | AA6: 约 4 秒/80 帧 | AC6: 多实体动作响应、显式状态更新、流式 action conditioning | AD6: 先下载测试集，再按事件/动作覆盖抽 20–35 小时 | AE6: 4–8 秒 | AF6: CC BY-NC-SA 4.0；商业使用另受 Epic 条款 | AG6: 符合非商业与访问条款时可用于研究 | AH6: 保存许可与Epic条款快照 | AI6: frames/actions/events/physics可对齐 | AJ6: 单一游戏域、bot 行为、无音频、固定 UI | AK6: 多实体动作响应、显式状态更新、流式 action conditioning ; 动作与逐帧状态完整；非人类、无音频 | AL6: https://mira-wm.com ; https://huggingface.co/datasets/kyutai/rocket-science ; https://github.com/mira-wm/mira | AM6: 高 | AN6: Rocket Science (MIRA)
A7: ViCo | B7: 系统+深研 | C7: C ; 数字人/说话者-倾听者/非语言反馈 | D7: 视听对话/听者反应 ; 配对 speaking-listening 视频 | E7: 2021-12 / ECCV 2022 | F7: 项目页提供直接下载 | G7: 项目页 OneDrive 直接下载 | H7: P0 | I7: A | J7: A | K7: P0 | L7: 3.07 | M7: 3.95 | N7: 下载全量并核验 research-only 许可 | O7: 95min全量 | P7: 全量 | Q7: <20GB ; 小 | R7: 95 分钟 ; 483 clips；92 identities ; 双人对话 | T7: 固定头像/近景 | U7: RGB,Face,Upper,Lip,Expression,Gaze,Audio,Listener ; 音频:是；独立 wav ; 语音:是 | V7: speaker/listener ID ; 是 ; 部分 | W7: 是；独立 wav ; 是 ; 弱 | X7: 倾听反馈 ; clip级 positive/neutral/negative；可提取头动/表情 ; 听者行为稀缺，规模小也高价值 | Y7: 否 | Z7: HHI ; 说话者-倾听者配对 ; 明确 speaker-listener 配对 ; 多人/双人 | AA7: 长视频:否 ; 完整episode:否 ; 长上下文:部分 ; 约11.8秒（粗算） | AB7: Stage 2/5 | AC7: 点头、微笑、注视、倾听态度和非语言反馈 | AD7: 全量使用；VLM提取细粒度 listener event | AE7: 6–12 秒 | AF7: 仅研究用途 restricted license | AG7: 研究用途，遵守受限许可 ; 需法务复核 | AH7: 保存research-only许可 | AI7: speaker/listener/audio无缺失 | AJ7: 规模小、仅头部、对话转录弱 ; 数据状态和许可未完全核实 | AK7: 点头、微笑、注视、倾听态度和非语言反馈 ; 小而关键，正中倾听行为 ; 听者行为稀缺，规模小也高价值 | AL7: https://project.mhzhou.com/vico ; https://vico.solutions/ | AM7: 高 | AN7: ViCo
A8: BEAT2 | B8: 系统+深研 | C8: C ; 数字人/全身+手+脸/语音 | D8: 整体对话动作扩展 ; BEAT经SMPL-X+FLAME重建与修正 | E8: 2024-01 | F8: 公开可用 | G8: 官方项目 ; 下载并渲染10段 | H8: P1 | I8: S | J8: S | K8: P1 | L8: 2.46 | M8: 4.3 | N8: 下载并渲染10段 | O8: 10 clips | P8: 2–4h | Q8: 0.1–0.4TB ; 中等 | R8: 精确有效小时数以BEAT2数据卡为准 ; 扩展整体动作 | T8: 3D mesh，可任意渲染 | U8: Audio,Text,MoCap,FullBody,Hand,FaceKP,HandKP,BodyKP,SMPLX,Expression ; 音频:是 ; 语音:是 ; 深度:可渲染 ; 相机:可控 | V8: speaker ID ; 是 ; 部分 | W8: 是 ; 弱 | X8: 是 ; SMPL-X body + FLAME face + hands ; 接近脸-手-身体整体协同目标 | Y8: 人物表达/动作状态 ; 否 | Z8: Speaker ; 多说话者 ; 弱/部分 ; 单人为主 | AA8: 长视频:否 ; 完整episode:否 ; 长上下文:部分 | AB8: Stage 2 | AC8: 同步面部、手势、全身动作与语音 | AD8: 优先于BEAT原版作动作条件；少量渲染混入 | AE8: 4–10 秒 | AF8: 非商业/项目条款 | AG8: 非商业研究可行 ; 需法务复核 | AH8: 保存非商业许可 | AI8: 音频-网格-渲染同步 | AJ8: 重建误差、非真实背景、交互双方不完整 ; 公开内容和许可需逐项确认 | AK8: 同步面部、手势、全身动作与语音 ; 数字人动作条件最实用 ; 接近脸-手-身体整体协同目标 | AL8: https://pantomatrix.github.io/EMAGE ; https://pantomatrix.github.io/BEAT2/ | AM8: 高 | AN8: BEAT2
A9: BEDD | B9: 深研 | C9: 游戏/人类演示/偏好 | D9: 人类完成四类模糊 Minecraft 任务 | E9: 2023-12 | F9: 可用 | G9: 安装并读100轨迹 | H9: P1 | J9: A | K9: P1 | M9: 3.87 | N9: 安装并读100轨迹 | O9: 100 trajectories | P9: 20–24h | Q9: 0.2–1TB | R9: 近 14,000 视频；26M image-action pair；3,000+ 人评 | T9: 第一人称 | X9: 是 ; image-action pair ; MineRL 动作空间 | Y9: 可通过环境重放获取 ; 可推导 | Z9: 单人 | AC9: 高层意图到动作、任务成功、人类偏好 Judge | AD9: 保留成功轨迹；偏好数据用于 VLM Judge | AE9: 6–12 秒 | AF9: 需结合 MineRL 与 Minecraft EULA | AG9: 研究用途通常可行 | AH9: 核查EULA | AI9: 逐step动作对齐且可重放 | AJ9: 仅四类任务、无音频、视觉域单一 | AK9: 高层意图到动作、任务成功、人类偏好 Judge ; 任务成功与偏好数据强 | AL9: https://github.com/minerllabs/basalt-benchmark | AM9: 高 | AN9: BEDD (MineRL BASALT)
A10: DROID | B10: 系统+深研 | C10: E ; 机器人/真实物体操作/动作状态 | D10: 大规模真实机器人操作 ; 13 机构、50 采集者、564 场景 | E10: 2024-03；2025 更新标定/语言 | F10: 公开可用 | G10: 官方项目 ; 流式读100 episodes | H10: P1 | I10: A | J10: S | K10: P1 | L10: 2.46 | M10: 4.15 | N10: 流式读100 episodes | O10: 100 episodes | P10: 8–12h | Q10: 0.2–0.8TB ; 全量较大；可流式读取 | R10: 350 小时 ; 76k demonstration trajectories ; 多机构真实操作 | S10: ZED2 外部 + ZED Mini 腕部；依数据流 | T10: 多第三人称 + 腕部 | U10: RGB,MultiView,CameraPosePartial,Long ; 音频:否/非核心 ; 语音:否 ; 深度:双目/深度可用 ; 相机:1,417 视点；提供标定 | V10: 无核心真人身份 ; 否 | W10: 否/非核心 ; 否 | X10: 是 ; 逐 step 连续机器人 action ; Oculus 遥操作；公开为机器人 action ; UserInput,Action ; 真实物理交互补模拟器域差 | Y10: 机器人 state 明确；对象状态需视觉推断 ; 可由前后帧与动作推导 ; 否 | Z10: UserInput,Action,HOI,Episode,FailurePartial ; 机器人主体 ; 否 ; 无人物/未核实 | AA10: 长视频:是 ; 完整episode:是 ; 长上下文:是 ; 约 16.6 秒（由总时长/轨迹数粗算） | AB10: Stage 3/4 | AC10: 拿取、放置、推拉、开关、工具操作的动作-视觉因果 | AD10: 取 8–15 小时日常操作；连续动作映射为语义 action token | AE10: 4–8 秒 | AF10: 官方项目/TFDS 条款；下载前复核 | AG10: 通常可行；需确认 ; 需法务复核 | AH10: 保存条款 | AI10: 相机/action/语言/标定可解析 | AJ10: 机器人视觉域；失败轨迹；对象状态非统一标签 ; 机器人形态和人物视频差异 | AK10: 拿取、放置、推拉、开关、工具操作的动作-视觉因果 ; 动作精确、场景多，机器人域 ; 真实物理交互补模拟器域差 | AL10: https://droid-dataset.github.io ; https://github.com/droid-dataset ; https://droid-dataset.github.io/ | AM10: 高 | AN10: DROID
A11: MineRL | B11: 系统+深研 | C11: E ; 游戏/人类演示/动作条件 | D11: Minecraft人类玩家动作日志 ; 人类 Minecraft 任务演示，可重模拟 | E11: 2019-07 | F11: 可用；需处理版本兼容 | G11: 官方API/镜像 ; 安装并读100轨迹 | H11: P1 | I11: S | J11: A | K11: P1 | L11: 2.5 | M11: 3.92 | N11: 安装并读100轨迹 | O11: 100 trajectories | P11: 20–24h | Q11: 0.2–1TB ; 版本不同 | R11: 60M+ state-action pair ; 长episode | S11: 常用观测 64×64；版本不同 ; 常用 20Hz | T11: 第一人称 | U11: RGB,AudioPartial,Long,Timestamp ; 音频:通常否 ; 语音:否 | V11: 匿名轨迹 ID ; 轨迹内支持 ; 否 | W11: 通常否 ; 否 ; 部分 | X11: 是 ; 逐 step 键鼠/环境动作 ; 键盘、鼠标、离散/连续控制 ; UserInput,Keyboard,Mouse,Action ; 少数真正对齐像素流与人类动作输入的数据 | Y11: 可从环境状态恢复 ; 可推导 ; 是 | Z11: UserInput,Keyboard,Mouse,Action,Replay,Counterfactual,State,Episode ; 单人玩家为主 ; 无人物/未核实 | AA11: 长视频:是 ; 完整episode:是 ; 长上下文:是 ; 轨迹长度不一 | AB11: Stage 4/5/6 | AC11: 第一人称移动、视角、采集/放置/制作 | AD11: 与 BEDD 合并，优先高状态变化轨迹 | AE11: 4–8 秒 + 长上下文索引 | AF11: MineRL 条款 + Minecraft EULA | AG11: 研究用途通常可行；商业需额外核查 ; 需法务复核 | AH11: 核查EULA | AI11: 逐step动作对齐且可重放 | AJ11: 分辨率低、旧版本、无音频、任务偏置 ; 游戏域、版本和许可证 | AK11: 第一人称移动、视角、采集/放置/制作 ; 动作/状态强；画质与兼容性弱 ; 少数真正对齐像素流与人类动作输入的数据 | AL11: https://minerl.io ; https://minerl.readthedocs.io/en/latest/tutorials/dataset.html ; https://github.com/minerllabs/minerl ; https://minerl.io/ | AM11: 中高 | AN11: MineRL
A12: TEACh | B12: 系统+深研 | C12: E ; 合成具身/对话协作 | D12: 对话式具身任务 ; AI2-THOR Commander-Follower 人类对话与动作 | E12: 2021-10 | F12: 可用 | G12: 官方项目/GitHub ; 跑通任务渲染 | H12: P1 | I12: S | J12: S | K12: P1 | L12: 2.43 | M12: 4.46 | N12: 跑通任务渲染 | O12: 10 trajectories | P12: 8–12h | Q12: 0.2–0.6TB | R12: 3,000+ 人-人任务对话；扩展标注约 39.5k utterances ; 多轮任务episode | T12: Follower 第一人称；可渲染其他视角 | U12: Text,DialogueAct,Long ; 音频:核心为文本 ; 语音:文本而非原始语音 ; 深度:可获取 ; 相机:可获取 | V12: Commander/Follower 角色 ID ; 是 ; 否 | W12: 核心为文本 ; 文本而非原始语音 ; 否 | X12: 是 ; 逐步导航与操作 ; 高层离散动作 ; UserInput,Instruction,Action ; 多轮用户指令、纠正和任务状态 | Y12: 是 | Z12: UserInput,Instruction,Action,State,Failure,Recovery,Episode ; 双角色 ; 发令者/执行者 ; 无人物/未核实 | AA12: 长视频:是 ; 完整episode:是 ; 长上下文:是 | AB12: Stage 4/5/6 | AC12: NPC 对话意图、纠错、行动反馈、状态一致性 | AD12: 合成语音；构造打断/改口/失败恢复 | AE12: 8–16 秒 | AF12: 项目与 AI2-THOR 条款按版本核查 | AG12: 研究用途可行 ; 需法务复核 | AH12: 保存代码与资产许可 | AI12: 自动生成before/action/after | AJ12: 无真实语音/真人视频，仿真域 ; 无真实音视频人物 | AK12: NPC 对话意图、纠错、行动反馈、状态一致性 ; 对话纠错和任务执行高度适配 ; 多轮用户指令、纠正和任务状态 | AL12: https://teaching-ai.github.io ; https://github.com/alexa/teach ; https://teachingalfred.github.io/ | AM12: 中高 | AN12: TEACh
A13: VirtualHome | B13: 系统+深研 | C13: E ; 合成家庭环境/程序动作/状态图 | D13: 多人物家庭活动模拟 ; 活动程序 + Unity3D 可执行模拟 | E13: 2018-06 | F13: 可用/可自行生成 | G13: 官方项目/GitHub ; 跑通任务渲染 | H13: P1 | I13: S | J13: S | K13: P1 | L13: 3.39 | M13: 4.41 | N13: 跑通任务渲染 | O13: 10 trajectories | P13: 8–12h | Q13: 0.2–0.6TB ; 中等；生成视频自定 | R13: 可自行生成 ; 可程序化生成 ; 程序化家庭活动 | S13: 可配置 | T13: 第一/第三人称/固定镜头 | U13: RGB,FullBody,Long ; 音频:默认无/弱 ; 语音:文本指令 ; 深度:可渲染 ; 相机:可获得 | V13: 虚拟角色 ID ; 是 ; 否 | W13: 默认无/弱 ; 文本指令 ; 可后配 ; 否 | X13: 是 ; 原子动作序列 ; 可映射高层动作 ; Instruction,Action ; 比纯机器人模拟更接近NPC和人物活动 | Y13: 显式 scene graph ; 显式可得 ; 是 | Z13: HHIPartial,HOI,HEI,MultiAgent,Instruction,Action,Replay,Counterfactual,State,Episode ; 虚拟人；可扩展多实体 ; 可扩展 ; 多人/双人 | AA13: 长视频:是 ; 完整episode:是 ; 长上下文:是 ; 可配置 | AB13: Stage 3/4/6 | AC13: 统一状态转换、scene graph、反事实动作 | AD13: 生成 5–15 小时高密度状态真值 | AE13: 4–10 秒；1–3 个原子变化 | AF13: 代码与 Unity 资产需分别核查 | AG13: 通常可行；保留资产许可记录 ; 需法务复核 | AH13: 保存代码与资产许可 | AI13: 自动生成before/action/after | AJ13: 视觉真实感和接触自然度有限 ; 动画真实性、接触与资产许可 | AK13: 统一状态转换、scene graph、反事实动作 ; 显式状态极强，视觉域偏合成 ; 比纯机器人模拟更接近NPC和人物活动 | AL13: http://virtual-home.org ; https://github.com/xavierpuigf/virtualhome ; http://virtual-home.org/ | AM13: 高 | AN13: VirtualHome
A14: Ego-Exo4D | B14: 系统+深研 | C14: D ; 多视角/技能活动 | D14: 同步第一/第三人称技能活动 ; 13 城市、740 人、123 场地、8 类技能 | E14: 2023-11 / CVPR 2024 | F14: 可申请下载 | G14: 官方门户+协议 ; 签新许可 | H14: P2 | I14: S | J14: S | K14: P2 | L14: 3.11 | M14: 4.15 | N14: 签新许可 | O14: sample subset | P14: 5–10h | Q14: 0.5–2TB ; 极大；多视角多模态 | R14: 1,286.3 小时（ego+exo） ; 5,035 takes ; 1,286.3小时；5,035 takes | S14: Aria RGB + 4–5 GoPro；依设备 ; 多设备同步；见 metadata | T14: 同步第一人称 + 4–5 第三人称 | U14: RGB,Audio,MultiChannel,FullBody,Hand,Gaze,IMU,CameraPose,PointCloud,BodyKP,HandKP,MultiView,Long ; 音频:7 麦克风阵列 ; 语音:是 ; 深度:Aria/点云派生 ; 相机:6DoF localization/相机位姿 | V14: participant ID；受许可约束 ; 是 ; 否 | W14: 7 麦克风阵列 ; 是 | X14: 是 ; keystep/atomic action/skill ; 否 ; 跨视角世界模型与多传感器关键资产 | Y14: 技能步骤与 3D 场景 ; 可从多视角与步骤推导 ; 否 | Z14: HOI,HEI,Episode ; 单人或多人技能活动 ; 部分场景 ; 单人为主 | AA14: 长视频:是 ; 完整episode:是 ; 长上下文:是 ; 1–42 分钟 | AB14: Stage 1/3/6 | AC14: 参考图/多视角一致性、技能动作、身份与空间一致性 | AD14: 抽 5–10 小时与任务接近的 cooking/bike repair/health 子集 | AE14: 6–12 秒 | AF14: 自定义许可；需重新签署 | AG14: 需依许可核查 ; 需法务复核 | AH14: 归档协议 | AI14: 下载目标技能子集 | AJ14: 多视角体积与同步成本高；无低层控制 ; 数据极大、同步复杂、协议与隐私 | AK14: 参考图/多视角一致性、技能动作、身份与空间一致性 ; 多视角强，处理成本很高 ; 跨视角世界模型与多传感器关键资产 | AL14: https://ego-exo4d-data.org ; https://docs.ego-exo4d-data.org ; https://github.com/facebookresearch/Ego4d ; https://ego-exo4d-data.org/ | AM14: 高 | AN14: Ego-Exo4D
A15: RH20T | B15: 深研 | C15: 机器人/多模态接触交互 | D15: 真实机器人多平台、多相机、多技能 | E15: 2023-07 | F15: 公开可下载 | G15: 只下320×180一个配置 | H15: P2 | J15: A | K15: P2 | M15: 3.91 | N15: 只下320×180一个配置 | O15: 1 config pilot | P15: 5–8h | Q15: 0.1–0.5TB ; 原始约40TB；640×360 RGB约5TB/RGBD约10TB；320×180显著更小 | R15: 110,000+ contact-rich sequences | S15: 原始1280×720；另有640×360、320×180 ; RGB/Depth 10Hz；力/位姿更高频 | T15: 8–10 全局 RGB-D + 1–2 手眼相机 | U15: 音频:是 ; 语音:可能含人声；非核心转录 ; 深度:是 ; 相机:完整标定 | V15: 人类示范可能含人脸/声音 ; 非核心 | W15: 是 ; 可能含人声；非核心转录 | X15: 是 ; joint/tcp/gripper/force-torque 多频率 ; 触觉设备/踏板遥操作；公开为机器人控制 | Y15: 机器人低维状态/完成评分 ; 可视觉推导 | Z15: 机器人；每条可配人类示范 ; 否 | AC15: 接触、工具、力学事件、动作结果与环境声音 | AD15: 只下320×180的1–2个配置，取5–10小时 | AE15: 4–8 秒 | AF15: 项目页限制与敏感内容要求；正式 license 需确认 | AG15: 建议仅研究并遵守敏感内容限制 | AH15: 核查敏感内容条款 | AI15: RGB/LowDim/audio时间对齐 | AJ15: 多配置异构、巨大、机器人域、压缩深度误差 | AK15: 接触、工具、力学事件、动作结果与环境声音 ; 音频/力/动作强，体量大 | AL15: https://rh20t.github.io ; https://github.com/rh20t | AM15: 高 | AN15: RH20T
A16: AI2-THOR | B16: 系统 | C16: E | D16: 可交互室内模拟器 | E16: 2017 | F16: 开源环境 | G16: pip/GitHub | I16: S | K16: S | L16: 2.54 | N16: 是 | R16: 可无限生成 | U16: RGB,Depth,CameraPose,Timestamp | V16: 否 | W16: 否 | X16: UserInput,Action ; 两周内最易构建可重放动作-状态数据 | Y16: 是 | Z16: UserInput,Action,Replay,Counterfactual,State,Failure,Recovery,Episode ; 无人物/未核实 | AA16: 长视频:否 ; 完整episode:是 ; 长上下文:是 | AB16: Stage 4/6 | AC16: 两周内最易构建可重放动作-状态数据 | AD16: 先取最小可用子集，完成许可和质量审计后扩展 | AE16: 4–12秒；长时阶段保留32秒至完整episode | AF16: 代码Apache 2.0；资产条款分离 | AG16: 需法务复核 | AJ16: 无自然人物；视觉域差 | AK16: 两周内最易构建可重放动作-状态数据 | AL16: https://ai2thor.allenai.org/ | AM16: 高 | AN16: AI2-THOR
A17: ALFRED | B17: 系统+深研 | C17: E ; 合成具身/语言指令/长程任务 | D17: 语言指令室内多步任务 ; AI2-THOR 专家轨迹与自然语言 | E17: 2019-12 | F17: 可用 | G17: 官方项目/GitHub | I17: S | J17: S | K17: S | L17: 2.54 | M17: 4.47 | N17: 是 | R17: 约 25k 自然语言指令；轨迹数按版本 ; 多步任务 | T17: 第一人称 | U17: RGB,Text,Long ; 音频:否 ; 语音:文本 ; 深度:可获得 ; 相机:可获得 | V17: 代理 ID ; 是 ; 否 | W17: 否 ; 文本 | X17: 是 ; 导航+操作原子动作 ; 高层离散动作 ; UserInput,Instruction,Action ; 结构清晰，适合Schema与状态差分验证 | Y17: 是 | Z17: UserInput,Instruction,Action,State,Failure,Replay,Counterfactual,Episode ; 单智能体 ; 否 ; 无人物/未核实 | AA17: 长视频:是 ; 完整episode:是 ; 长上下文:是 | AB17: Stage 4/6 | AC17: 语言计划→动作→状态变化、长程任务 | AD17: 渲染关键步骤，构造 before/action/after | AE17: 6–12 秒局部窗 + 完整任务元数据 | AF17: 项目与 AI2-THOR 条款按版本核查 | AG17: 研究用途可行 ; 需法务复核 | AJ17: 仿真域、离散动作、无真人/音频 ; AI2-THOR域、动作离散 | AK17: 语言计划→动作→状态变化、长程任务 ; 语言-动作-状态链完整 ; 结构清晰，适合Schema与状态差分验证 | AL17: https://askforalfred.com ; https://github.com/askforalfred/alfred ; https://askforalfred.com/ | AM17: 高 | AN17: ALFRED
A18: AMI Meeting Corpus | B18: 系统 | C18: C | D18: 多方会议音视频 | E18: 2005 | F18: 公开/注册条款 | G18: 官方门户 | I18: S | K18: S | L18: 3.32 | N18: 是（可用部分） | R18: 约100小时 | U18: RGB,Audio,MultiChannel,Text,ASRPartial,SpeakerID,VAD,DialogueAct,Listener,Long | V18: 是 | W18: 是 | X18: 轮次、重叠和backchannel仍不可替代 | Y18: 否 | Z18: HHI,Overlap ; 多人/双人 | AA18: 长视频:是 ; 完整episode:否 ; 长上下文:是 | AB18: Stage 2/3/5/6 | AC18: 轮次、重叠和backchannel仍不可替代 | AD18: 先取最小可用子集，完成许可和质量审计后扩展 | AE18: 4–12秒；长时阶段保留32秒至完整episode | AF18: 研究用途 | AG18: 需法务复核 | AJ18: 分辨率低、会议域单一 | AK18: 轮次、重叠和backchannel仍不可替代 | AL18: https://groups.inf.ed.ac.uk/ami/corpus/ | AM18: 高 | AN18: AMI Meeting Corpus
A19: AVSpeech | B19: 系统 | C19: C | D19: 大规模单说话人音视频 | E19: 2018 | F19: 公开CSV索引；原视频自行下载 | G19: YouTube ID+时间戳+脸位置 | I19: S | K19: S | L19: 2.57 | N19: 是（先10小时） | R19: 约4700小时 | U19: RGB,Face,Upper,Lip,Audio,VAD | V19: 是 ; 部分 | W19: 是 | X19: 音画同步、口型和说话人面部运动核心 | Y19: 否 | Z19: Speaker ; 单人为主 | AA19: 长视频:否 ; 完整episode:否 ; 长上下文:部分 | AB19: Stage 2 | AC19: 音画同步、口型和说话人面部运动核心 | AD19: 先取最小可用子集，完成许可和质量审计后扩展 | AE19: 4–12秒；长时阶段保留32秒至完整episode | AF19: 索引公开；原视频权利由来源决定 | AG19: 需法务复核 | AJ19: 只有说话者；YouTube失效与权利风险 | AK19: 音画同步、口型和说话人面部运动核心 | AL19: https://looking-to-listen.github.io/avspeech/ | AM19: 高 | AN19: AVSpeech
A20: BEHAVIOR-1K/OmniGibson | B20: 系统+深研 | C20: E ; 合成具身/物理交互/长程状态 | D20: 1000类家庭长任务模拟 ; OmniGibson 物理仿真 | E20: 2024-03 | F20: 可用/工程成本高 | G20: 官方项目/GitHub | I20: S | K20: S | L20: 3.07 | N20: 是（10任务） | Q20: 环境/资产较大；视频另计 | R20: 可自行生成 ; 1,000 活动；50 场景；9,000+ 物体 ; 1000任务 | S20: 可配置 | T20: 第一/第三人称可配置 | U20: RGB,Depth,Long ; 音频:默认非核心 ; 语音:文本任务 ; 深度:是 ; 相机:是 | V20: 虚拟实体 ID ; 是 ; 否 | W20: 默认非核心 ; 文本任务 ; 可扩展 ; 否 | X20: 是 ; 任务/技能/连续控制 ; 可映射 ; Action ; 状态监督和多步骤任务最强资产之一 | Y20: 显式物理与语义属性 ; 显式可得 ; 是 | Z20: HOI,HEI,MultiAgentPartial,Action,Replay,Counterfactual,State,Failure,Recovery,Episode ; 机器人/虚拟主体 ; 可扩展 ; 无人物/未核实 | AA20: 长视频:是 ; 完整episode:是 ; 长上下文:是 ; 长程任务 | AB20: Stage 3/4/6 | AC20: 液体、软体、容器、开关等复杂状态转移 | AD20: 只选 3–8 类关键状态，不铺满 1,000 活动 | AE20: 6–16 秒 | AF20: 代码与资产分别核查 | AG20: 通常可行；遵守资产条款 ; 需法务复核 | AJ20: 域差距、复杂物理渲染慢且可能不稳定 ; 物理/视觉域差与安装成本 | AK20: 液体、软体、容器、开关等复杂状态转移 ; 状态监督和多步骤任务最强资产之一 | AL20: https://behavior.stanford.edu ; https://github.com/StanfordVL/BEHAVIOR-1K ; https://behavior.stanford.edu/ | AM20: 高 | AN20: BEHAVIOR-1K/OmniGibson ; BEHAVIOR-1K / OmniGibson
A21: BridgeData V2 | B21: 系统+深研 | C21: E ; 机器人/日常物体操作/语言 | D21: 多任务真实机器人操作 ; 低成本机器人在24环境执行任务 | E21: 2023-08 | F21: 公开可用 | G21: 官方项目 | I21: A | J21: S | K21: S | L21: 2.5 | M21: 4.15 | N21: 是（小子集） | Q21: 较大 | R21: 60,096 trajectories ; 真实操作轨迹 | T21: 第三人称/机器人视角 | U21: RGB,Text,Long ; 音频:否 ; 语音:否 | V21: 无 ; 否 | W21: 否 | X21: 是 ; 连续机器人 action ; 遥操作映射为action ; UserInput,Instruction,Action ; 工程可用的真实动作条件数据 | Y21: 机器人state；对象状态视觉推断 ; 可推导 ; 否 | Z21: UserInput,Instruction,Action,HOI,Episode ; 机器人 ; 否 ; 无人物/未核实 | AA21: 长视频:是 ; 完整episode:是 ; 长上下文:是 | AB21: Stage 3/4 | AC21: 日常物体动作、语言条件、目标图像条件 | AD21: DROID轻量补充；选5–8小时 | AE21: 4–8 秒 | AF21: 项目许可需核查 | AG21: 通常可行 ; 需法务复核 | AJ21: 机器人域；相机/动作格式需适配 ; 机器人域与构图差异 | AK21: 日常物体动作、语言条件、目标图像条件 ; 日常操作与语言强 ; 工程可用的真实动作条件数据 | AL21: https://rail-berkeley.github.io/bridgedata ; https://github.com/rail-berkeley/bridge_data_v2 ; https://rail-berkeley.github.io/bridgedata/ | AM21: 中高 | AN21: BridgeData V2
A22: CelebV-Text | B22: 系统 | C22: B | D22: 人脸视频-细粒度文本 | E22: 2023 | F22: 下载流程公开；非商业协议 | G22: 官方页面/脚本 | I22: S | K22: S | L22: 2.54 | N22: 是（许可后） | R22: 70K片段；279小时 | U22: RGB,Face,Upper,Lip,Expression,Identity,Text,HumanCaption,AudioPartial | V22: 是 | W22: 部分 | X22: 人物视频文本对齐与可控生成价值高 | Y22: 否 | Z22: Human ; 单人为主 | AA22: 长视频:否 ; 完整episode:否 ; 长上下文:部分 | AB22: Stage 1/2 | AC22: 人物视频文本对齐与可控生成价值高 | AD22: 先取最小可用子集，完成许可和质量审计后扩展 | AE22: 4–12秒；长时阶段保留32秒至完整episode | AF22: 仅非商业研究；禁止再分发 | AG22: 需法务复核 | AJ22: 名人/互联网来源及非商业限制 | AK22: 人物视频文本对齐与可控生成价值高 | AL22: https://celebv-text.github.io/ | AM22: 高 | AN22: CelebV-Text
A23: EPIC-SOUNDS | B23: 系统+深研 | C23: D ; 音频事件/人-物交互声音 | D23: 第一人称声音事件 ; EPIC-KITCHENS-100原始音频 | E23: 2023 | F23: 公开可用 | G23: 官方项目 | I23: A | J23: S | K23: S | L23: 2.43 | M23: 4.35 | N23: 否（随EPIC申请） | Q23: 音频本身较小 | R23: 44类交互声音；事件数见官方split ; 动作声音事件 | T23: 第一人称 | U23: Audio,Text,ActionBoundary ; 音频:是 ; 语音:可能混有 | V23: participant ID ; 是 ; 否 | W23: 是 ; 可能混有 | X23: 声音动作事件 ; trimmed/untrimmed时间段 ; 补足动作音效和环境声音结果 | Y23: 可与EPIC动作标签联合 ; 可推导 ; 否 ; 部分 | Z23: HOIPartial,StatePartial ; 单人 ; 单人为主 | AA23: 长视频:否 ; 完整episode:否 ; 长上下文:部分 | AB23: Stage 2/3 | AC23: 开门、切割、碰撞、放置、脚步等AV同步 | AD23: 与EPIC按时间戳join；用于音频事件头和AV Judge | AE23: 2–6 秒 | AF23: CC BY-NC 4.0 | AG23: 非商业研究可行 ; 需法务复核 | AJ23: 需与视频重对齐；语音可能干扰声音事件 ; 与视觉源绑定，许可继承 | AK23: 开门、切割、碰撞、放置、脚步等AV同步 ; 与EPIC视频天然对齐 ; 补足动作音效和环境声音结果 | AL23: https://epic-kitchens.github.io/epic-sounds ; https://epic-kitchens.github.io/2026 ; https://github.com/epic-kitchens ; https://epic-kitchens.github.io/epic-sounds/ | AM23: 高 | AN23: EPIC-SOUNDS
A24: HD-EPIC | B24: 深研 | C24: 高密度第一人称/状态/3D/音频 | D24: 9 个真实家庭厨房 | E24: 2025-02 | F24: 项目公开；下载条款需确认 | J24: S | K24: S | M24: 4.39 | R24: 41 小时 ; 9 kitchens；69 recipes；26k VQA | S24: 高清；查 metadata | T24: 第一人称 | U24: 音频:是 ; 语音:可能/非核心 ; 深度:数字孪生/3D grounding ; 相机:3D grounding | V24: participant ID ; 是 | W24: 是 ; 可能/非核心 ; 是；51k audio events | X24: 是 ; 59k 细粒度动作 | Y24: 强 ; 强；对象移动与食材/步骤状态 | Z24: 单人佩戴者为主 | AA24: 长序列 | AC24: 细粒度动作、音频事件、3D 状态与长时追踪 | AD24: 优先作验证/评估与高质量小规模微调 | AE24: 4–10 秒 | AF24: 正式下载条款需核查 | AG24: 需确认 | AJ24: 仅 9 个厨房；训练条款需确认 | AK24: 细粒度动作、音频事件、3D 状态与长时追踪 ; 状态/音频/3D 标注密度高 | AL24: https://hd-epic.github.io | AM24: 高 | AN24: HD-EPIC
A25: MineDojo | B25: 系统 | C25: E | D25: Minecraft知识+交互环境 | E25: 2022 | F25: 环境、代码和数据说明公开 | G25: 官方GitHub/下载 | I25: S | K25: S | L25: 2.54 | N25: 是（环境+任务） | R25: 大规模任务 | U25: RGB,Text,Long | V25: 否 | W25: 否 | X25: Instruction,Action ; 可控、可重放、可生成反事实 | Y25: 是 | Z25: Instruction,Action,Replay,Counterfactual,State,Episode ; 无人物/未核实 | AA25: 长视频:是 ; 完整episode:是 ; 长上下文:是 | AB25: Stage 4/6 | AC25: 可控、可重放、可生成反事实 | AD25: 先取最小可用子集，完成许可和质量审计后扩展 | AE25: 4–12秒；长时阶段保留32秒至完整episode | AF25: 各数据源条款分离 | AG25: 需法务复核 | AJ25: 游戏域和多源许可 | AK25: 可控、可重放、可生成反事实 | AL25: https://minedojo.org/ | AM25: 高 | AN25: MineDojo
A26: OmniMMI | B26: 系统 | C26: F | D26: 流式视频多模态交互评测 | E26: 2025 | F26: 论文和基准发布；仓库/许可需核实 | G26: 论文/项目待定位 | I26: S | K26: S | L26: 3.0 | N26: 否（只做评测） | R26: 1,121视频；2,290问题；平均324秒 | U26: RGB,Audio,Text,HumanCaption,Long,Timestamp | V26: 是 ; 否 | W26: 是 | X26: UserInput,Instruction ; 流式状态、动作规划、主动响应和多轮依赖 | Y26: 否 ; 部分 | Z26: UserInput,Instruction,Streaming,StatePartial,MultiTurn ; 单人为主 | AA26: 长视频:是 ; 完整episode:否 ; 长上下文:是 | AB26: Stage 4/5/6评测 | AC26: 流式状态、动作规划、主动响应和多轮依赖 | AD26: 先取最小可用子集，完成许可和质量审计后扩展 | AE26: 4–12秒；长时阶段保留32秒至完整episode | AF26: 未核实 | AG26: 需法务复核 | AJ26: 混合来源和训练泄漏风险 | AK26: 流式状态、动作规划、主动响应和多轮依赖 | AL26: https://arxiv.org/abs/2503.22952 | AM26: 高 | AN26: OmniMMI
A27: OpenVid-1M | B27: 系统 | C27: A | D27: 高质量文本-视频 | E27: 2024 | F27: 已公开；按子集核实文件 | G27: HF/官方仓库 | I27: S | K27: S | L27: 1.96 | N27: 是（先取HD小子集） | R27: >1M片段；约433K 1080p | U27: RGB,Text,AutoCaption,AudioPartial | V27: 是 ; 否 | W27: 部分 | X27: 高质量通用视频回放与人物子集兼顾 | Y27: 否 | Z27: General ; 单人为主 | AA27: 长视频:否 ; 完整episode:否 ; 长上下文:部分 | AB27: Stage 0/1 | AC27: 高质量通用视频回放与人物子集兼顾 | AD27: 先取最小可用子集，完成许可和质量审计后扩展 | AE27: 4–12秒；长时阶段保留32秒至完整episode | AF27: 数据与代码条款需分开审计 | AG27: 需法务复核 | AJ27: 第三方来源权利与许可证口径需逐文件核实 | AK27: 高质量通用视频回放与人物子集兼顾 | AL27: https://github.com/NJU-PCALab/OpenVid-1M | AM27: 高 | AN27: OpenVid-1M
A28: ResponseNet | B28: 系统 | C28: C | D28: 在线双人多模态响应 | E28: 2025 | F28: 论文称数据代码模型公开；仓库待定位 | G28: 论文/项目仓库待定位 | I28: S | K28: S | L28: 3.25 | N28: 否（定位仓库/联系作者） | R28: 696个详细双人互动 | U28: RGB,Audio,Text,ASR,Face,Upper,Lip,Expression,Listener,MultiChannel | V28: 是 ; 部分 | W28: 是 | X28: 与在线听者语音+面部响应高度匹配 | Y28: 否 | Z28: HHI,Streaming ; 多人/双人 | AA28: 长视频:否 ; 完整episode:否 ; 长上下文:部分 | AB28: Stage 2/5 | AC28: 与在线听者语音+面部响应高度匹配 | AD28: 先取最小可用子集，完成许可和质量审计后扩展 | AE28: 4–12秒；长时阶段保留32秒至完整episode | AF28: 未核实 | AG28: 需法务复核 | AJ28: 下载和许可未完成官方交叉核实 | AK28: 与在线听者语音+面部响应高度匹配 | AL28: https://arxiv.org/abs/2505.21724 | AM28: 中 | AN28: ResponseNet
A29: SpeakerVid-5M | B29: 系统 | C29: C | D29: 大规模视听双人交互人像 | E29: 2025 | F29: HF已发布58.9GB标注/索引；原视频按YouTube ID下载 | G29: HF标注+代码+自行抓取 | I29: S | K29: S | L29: 3.5 | N29: 是（先下标注和小子集） | R29: >5.2M片段；>8,743小时 | U29: RGB,Audio,Text,ASR,Face,Upper,FullBody,Hand,Lip,Expression,Gesture,Listener,BodyKPPartial,SpeakerID | V29: 是 | W29: 是 | X29: 截至截止日最贴近数字人双人交互目标的公开资源之一 | Y29: 否 | Z29: HHI,MultiTurn ; 多人/双人 | AA29: 长视频:否 ; 完整episode:否 ; 长上下文:部分 | AB29: Stage 1/2/5 | AC29: 截至截止日最贴近数字人双人交互目标的公开资源之一 | AD29: 先取最小可用子集，完成许可和质量审计后扩展 | AE29: 4–12秒；长时阶段保留32秒至完整episode | AF29: 严格非商业科研/教育；有删除机制 | AG29: 需法务复核 | AJ29: 原视频版权/可用性；严格非商业；全量工程巨大 | AK29: 截至截止日最贴近数字人双人交互目标的公开资源之一 | AL29: https://huggingface.co/datasets/dorni/SpeakerVid-5M-Dataset | AM29: 高 | AN29: SpeakerVid-5M
A30: TalkingHead-1KH | B30: 系统 | C30: B | D30: 大规模头部视频 | E30: 2020 | F30: 元数据/脚本公开；原视频自行下载 | G30: YouTube ID+脚本 | I30: S | K30: S | L30: 2.68 | N30: 是（先1K样本） | R30: 约500K片段；80K高于512 | U30: RGB,Face,Upper,Lip,Expression,Audio,IdentityPartial | V30: 是 ; 部分 | W30: 是 | X30: 快速构建高质量talking-head smoke池 | Y30: 否 | Z30: Human ; 单人为主 | AA30: 长视频:否 ; 完整episode:否 ; 长上下文:部分 | AB30: Stage 1/2 | AC30: 快速构建高质量talking-head smoke池 | AD30: 先取最小可用子集，完成许可和质量审计后扩展 | AE30: 4–12秒；长时阶段保留32秒至完整episode | AF30: 入选视频声称宽松许可；逐来源复核 | AG30: 需法务复核 | AJ30: 原视频可用性、逐视频许可和sync复检 | AK30: 快速构建高质量talking-head smoke池 | AL30: https://github.com/tcwang0509/TalkingHead-1KH | AM30: 高 | AN30: TalkingHead-1KH
A31: VideoFDB | B31: 系统 | C31: F | D31: 全双工视听对话评测 | E31: 2026 | F31: 论文发布；数据下载状态待核实 | G31: 论文/待定位仓库 | I31: S | K31: S | L31: 3.36 | N31: 否（定位下载/联系作者） | R31: 237双人片段；11类动态 | U31: RGB,Audio,Face,Upper,Lip,Expression,Gaze,Gesture,Listener,SpeakerID,VAD,DialogueAct,Timestamp | V31: 是 | W31: 是 | X31: 目前最直接评测AV2AV全双工动态 | Y31: 否 | Z31: HHI,Overlap,Streaming ; 多人/双人 | AA31: 长视频:否 ; 完整episode:否 ; 长上下文:部分 | AB31: Stage 5评测 | AC31: 目前最直接评测AV2AV全双工动态 | AD31: 先取最小可用子集，完成许可和质量审计后扩展 | AE31: 4–12秒；长时阶段保留32秒至完整episode | AF31: 未核实 | AG31: 需法务复核 | AJ31: 规模小；必须独立测试 | AK31: 目前最直接评测AV2AV全双工动态 | AL31: https://arxiv.org/abs/2605.30256 | AM31: 高 | AN31: VideoFDB
A32: AMASS | B32: 系统 | C32: B | D32: 统一3D人体动作库 | E32: 2019 | F32: 需注册/各子库条款 | G32: 官方申请 | I32: A | K32: A | L32: 2.0 | N32: 否（立即申请） | R32: 4M+动作帧 | U32: MoCap,BodyKP,SMPLX,FullBody | V32: 否 ; 部分 | W32: 否 | X32: 统一SMPL动作表示，身体先验核心 | Y32: 否 | Z32: Human ; 无人物/未核实 | AA32: 长视频:否 ; 完整episode:否 ; 长上下文:部分 | AB32: Stage 1/2 | AC32: 统一SMPL动作表示，身体先验核心 | AD32: 先取最小可用子集，完成许可和质量审计后扩展 | AE32: 4–12秒；长时阶段保留32秒至完整episode | AF32: 研究用途；子库许可不同 | AG32: 需法务复核 | AJ32: 无RGB/音频；子库许可异质 | AK32: 统一SMPL动作表示，身体先验核心 | AL32: https://amass.is.tue.mpg.de/ | AM32: 高 | AN32: AMASS
A33: ARCTIC | B33: 系统+深研 | C33: D ; 双手/可动关节物体/接触 | D33: 双手与可动对象交互 ; 双手操作剪刀、笔记本等 articulated objects | E33: 2022-04 | F33: 可申请 | G33: 官方项目 | I33: A | J33: A | K33: A | L33: 2.61 | M33: 3.95 | N33: 否（立即申请） | Q33: 较大 | R33: 2.1M frames ; 多视角交互 | T33: 多视角/单目任务 | U33: RGB,MoCap,HandKP,SMPLX,CameraPose,MultiView ; 音频:否 ; 语音:否 ; 相机:多视角标定 | V33: subject ID ; 是 ; 否 | W33: 否 | X33: 隐式连续操作 ; 逐帧3D mesh/contact ; 可动对象状态和双手接触稀缺 | Y33: 手-物接触与关节状态 ; 强 ; 否 ; 是 | Z33: HOI,StateChange ; 单人 ; 单人为主 | AA33: 长视频:否 ; 完整episode:否 ; 长上下文:部分 | AB33: Stage 1/3 | AC33: 关节物体状态、双手接触、物理一致性 | AD33: 2–5小时精确状态；辅助损失/评估 | AE33: 2–6 秒 | AF33: MPI/项目研究许可；需注册 | AG33: 需按许可核查 ; 需法务复核 | AJ33: 受控环境、对象类别有限、无音频/全身 ; 实验室域和协议 | AK33: 关节物体状态、双手接触、物理一致性 ; 接触与关节状态强 ; 可动对象状态和双手接触稀缺 | AL33: https://arctic.is.tue.mpg.de ; https://arctic.is.tue.mpg.de/ | AM33: 高 | AN33: ARCTIC
A34: BEAT | B34: 系统+深研 | C34: C ; 数字人/全身动作/语音/情绪 | D34: 语义情感对话手势 ; 30名说话者动作捕捉，自述与对话 | E34: 2022-03 | F34: 可用 | G34: 官方项目 | I34: S | J34: A | K34: A | L34: 2.29 | M34: 4.13 | N34: 否（立即申请） | Q34: 中等 | R34: 76小时3D motion ; 30 speakers；录制单元见数据卡 ; 约76小时 | T34: 3D动作；可渲染多视角 | U34: Audio,Text,MoCap,FullBody,HandPartial,Gesture,Emotion,BodyKP ; 音频:是 ; 语音:是 ; 相机:渲染可控 | V34: 30 speaker IDs ; 是 ; 部分 | W34: 是 ; 弱 | X34: 是 ; 逐帧手势语义/52D face blendshape/3D body motion ; 语音到全身手势的核心数据 | Y34: 人物表达状态 ; 否 | Z34: Speaker ; 单人说话为主；部分对话 ; 部分conversation；主要单人 ; 单人为主 | AA34: 长视频:否 ; 完整episode:否 ; 长上下文:部分 ; 自述约1分钟；对话约10分钟 | AB34: Stage 2 | AC34: 语音-全身手势-表情、情绪控制、数字人动作先验 | AD34: 渲染统一数字人视频，取4–8小时 | AE34: 4–10 秒 | AF34: Non-commercial license | AG34: 非商业研究可行 ; 需法务复核 | AJ34: 非真实RGB；对话交互比例有限 ; MoCap到真实RGB域差；单人偏差 | AK34: 语音-全身手势-表情、情绪控制、数字人动作先验 ; 动作与语音强，非真实RGB ; 语音到全身手势的核心数据 | AL34: https://pantomatrix.github.io/BEAT ; https://pantomatrix.github.io/BEAT/ | AM34: 高 | AN34: BEAT
A35: CALVIN | B35: 系统 | C35: E | D35: 语言条件长程机器人任务 | E35: 2021 | F35: 公开 | G35: 官方项目/GitHub | I35: A | K35: A | L35: 2.46 | N35: 是（小子集） | R35: 长程任务 | U35: RGB,Text,Long | V35: 否 | W35: 否 | X35: Instruction,Action ; 多步任务进度和记忆验证 | Y35: 是 | Z35: Instruction,Action,State,Episode ; 无人物/未核实 | AA35: 长视频:是 ; 完整episode:是 ; 长上下文:是 | AB35: Stage 4/6 | AC35: 多步任务进度和记忆验证 | AD35: 先取最小可用子集，完成许可和质量审计后扩展 | AE35: 4–12秒；长时阶段保留32秒至完整episode | AF35: 研究用途 | AG35: 需法务复核 | AJ35: 机器人桌面域 | AK35: 多步任务进度和记忆验证 | AL35: https://mees.github.io/calvin/ | AM35: 高 | AN35: CALVIN
A36: CHiME-6 | B36: 系统 | C36: C | D36: 远场多说话人对话 | E36: 2020 | F36: 需注册/协议 | G36: 官方挑战页 | I36: A | K36: A | L36: 2.61 | N36: 否（立即申请） | R36: 多通道家庭对话 | U36: Audio,MultiChannel,SpeakerID,VAD,RGBPartial | V36: 是 | W36: 是 | X36: 重叠语音和远场音频前端价值高 | Y36: 否 | Z36: HHI,Overlap ; 多人/双人 | AA36: 长视频:否 ; 完整episode:否 ; 长上下文:部分 | AB36: Stage 2/5 | AC36: 重叠语音和远场音频前端价值高 | AD36: 先取最小可用子集，完成许可和质量审计后扩展 | AE36: 4–12秒；长时阶段保留32秒至完整episode | AF36: 研究用途 | AG36: 需法务复核 | AJ36: 视频覆盖有限，主要是音频 | AK36: 重叠语音和远场音频前端价值高 | AL36: https://chimechallenge.github.io/chime6/ | AM36: 高 | AN36: CHiME-6
A37: CMU Panoptic | B37: 系统 | C37: B | D37: 多人物多视角3D动作 | E37: 2017 | F37: 部分序列公开 | G37: 官方服务器/脚本 | I37: A | K37: A | L37: 2.43 | N37: 是（小序列） | R37: 多序列 | U37: RGB,MultiPerson,FullBody,BodyKP,FaceKPPartial,MultiView | V37: 是 ; 部分 | W37: 否 | X37: 多人同步多视角与3D标注稀缺 | Y37: 否 | Z37: HHI ; 多人/双人 | AA37: 长视频:否 ; 完整episode:否 ; 长上下文:部分 | AB37: Stage 1/3 | AC37: 多人同步多视角与3D标注稀缺 | AD37: 先取最小可用子集，完成许可和质量审计后扩展 | AE37: 4–12秒；长时阶段保留32秒至完整episode | AF37: 研究用途 | AG37: 需法务复核 | AJ37: 实验室域、存储和处理成本 | AK37: 多人同步多视角与3D标注稀缺 | AL37: http://domedb.perception.cs.cmu.edu/ | AM37: 高 | AN37: CMU Panoptic
A38: DexYCB | B38: 深研 | C38: 手-物抓取/多视角RGB-D | D38: 10名受试者抓取20个YCB物体 | E38: 2021-04 | F38: 可申请 | J38: A | K38: A | M38: 3.58 | Q38: 较大 | R38: 1,000 sequences；约582k frames | T38: 8相机多视角 | U38: 音频:否 ; 语音:否 ; 深度:是 ; 相机:是 | V38: subject ID ; 是 | W38: 否 | X38: 抓取序列 ; 逐帧pose/segmentation | Y38: 手与物体状态 ; 可推导 | Z38: 10名受试者 ; 否 | AA38: 约582帧/序列（粗算） | AC38: 抓取姿态、手-物一致性、参考图保持 | AD38: 精确手-物辅助集/评估集 | AE38: 2–5 秒 | AF38: 研究许可需接受条款 | AG38: 需确认 | AJ38: 抓取任务窄、受控背景、无音频/全身 | AK38: 抓取姿态、手-物一致性、参考图保持 ; 抓取精确但任务窄 | AL38: https://dex-ycb.github.io ; https://github.com/NVlabs/dex-ycb-toolkit | AM38: 高 | AN38: DexYCB
A39: EgoCom | B39: 系统 | C39: C | D39: 第一人称多人对话 | E39: 2023 | F39: 公开状态需复核 | G39: 仓库/申请 | I39: A | K39: A | L39: 3.14 | N39: 否（测试链接） | R39: 长时多人对话 | U39: RGB,Audio,SpeakerID,VAD,Listener,Long | V39: 是 | W39: 是 | X39: 真实社交对话和长时听说视角 | Y39: 否 | Z39: HHI,Overlap ; 多人/双人 | AA39: 长视频:是 ; 完整episode:否 ; 长上下文:是 | AB39: Stage 2/3/5/6 | AC39: 真实社交对话和长时听说视角 | AD39: 先取最小可用子集，完成许可和质量审计后扩展 | AE39: 4–12秒；长时阶段保留32秒至完整episode | AF39: 未核实 | AG39: 需法务复核 | AJ39: 获取与许可需复核 | AK39: 真实社交对话和长时听说视角 | AL39: https://github.com/facebookresearch/EgoCom | AM39: 中 | AN39: EgoCom
A40: EgoExoLearn | B40: 深研 | C40: 第一/第三人称/程序活动/模仿学习 | D40: 真实技能；执行者观看示范后完成任务 | E40: 2024-03 | F40: 官方多渠道直接下载 | G40: Google Drive / 百度网盘 / Hugging Face | J40: A | K40: A | M40: 3.99 | N40: 下载 1 个技能子集 pilot | Q40: 未公开 | R40: 120 小时 | T40: 异步 ego + demonstration/exo | U40: 音频:部分/未确认 ; 语音:示范视频可能含语音 | V40: participant ID ; 是 | W40: 部分/未确认 ; 示范视频可能含语音 ; 可能 | X40: 是 ; 程序步骤/跨视角动作 | Y40: 步骤级可推导 ; 可推导 | Z40: 执行者与示范者 ; 示范者-执行者 | AA40: 程序活动长序列 | AC40: 观察示范→执行计划、参考视频条件、跨视角迁移 | AD40: 取 5–10 小时作 reference video/plan 数据 | AE40: 6–12 秒 | AF40: 仓库/数据条款需确认 | AG40: 需核查 | AJ40: ego/exo 异步；状态不显式 | AK40: 观察示范→执行计划、参考视频条件、跨视角迁移 ; reference video/跨视角强 | AL40: https://github.com/OpenGVLab/EgoExoLearn | AM40: 中高 | AN40: EgoExoLearn
...

Sheet 02_优先级与评分
A1: 数据集名称 | B1: 来源覆盖 | C1: 执行优先级 | D1: 整合行动级别 | E1: 系统优先级 | F1: 深研优先级 | G1: 系统28D总分 | H1: 系统28D平均分 | I1: 深研加权分 | J1: Interaction 10% | K1: Human 7% | L1: Action 9% | M1: State 10% | N1: Audio 5% | O1: Visual 6% | P1: Temporal 7% | Q1: Identity 5% | R1: Diversity 5% | S1: License 10% | T1: Access 8% | U1: Preprocess Ease 5% | V1: 5B FT 6% | W1: Streaming 4% | X1: Evaluation 3% | Y1: 评分冲突 | Z1: 解释
A2: Assembly101 | B2: 系统+深研 | C2: P0 | D2: P0 | E2: S | F2: S | G2: 72 | H2: 2.57 | I2: 4.45 | J2: 5 | K2: 5 | L2: 5 | M2: 5 | N2: 1 | O2: 5 | P2: 5 | Q2: 4 | R2: 4 | S2: 5 | T2: 5 | U2: 2 | V2: 4 | W2: 4 | X2: 5 | Z2: 多步骤、错误和纠正对状态/恢复关键 ; 动作和状态精细，多视角成本高
A3: EPIC-KITCHENS-100 | B3: 系统+深研 | C3: P0 | D3: P0 | E3: S | F3: S | G3: 86 | H3: 3.07 | I3: 4.61 | J3: 5 | K3: 5 | L3: 4 | M3: 5 | N3: 5 | O3: 4 | P3: 5 | Q3: 4 | R3: 4 | S3: 5 | T3: 5 | U3: 3 | V3: 5 | W3: 4 | X3: 5 | Z3: 真实无脚本HOI、动作意图和完整episode ; 首期最稳妥的真实状态变化数据
A4: EasyCom | B4: 系统+深研 | C4: P0 | D4: P0 | E4: S | F4: A | G4: 83 | H4: 2.96 | I4: 3.97 | J4: 5 | K4: 5 | L4: 3 | M4: 2 | N4: 5 | O4: 4 | P4: 5 | Q4: 4 | R4: 3 | S4: 4 | T4: 4 | U4: 3 | V4: 4 | W4: 5 | X4: 5 | Y4: 系统=S；深研=A | Z4: 多人、重叠、听者和多通道数据稀缺 ; 说话人归属与全双工感知强
A5: Ego4D | B5: 系统+深研 | C5: P0 | D5: P0 | E5: S | F5: S | G5: 85 | H5: 3.04 | I5: 4.15 | J5: 5 | K5: 5 | L5: 3 | M5: 5 | N5: 4 | O5: 4 | P5: 5 | Q5: 4 | R5: 5 | S5: 4 | T5: 3 | U5: 2 | V5: 4 | W5: 4 | X5: 5 | Z5: 现实长时交互、状态前后和记忆监督全面 ; 真实交互广，筛选/许可成本高
A6: MIRA Rocket Science | B6: 深研 | C6: P0 | D6: P0 | F6: A | I6: 3.88 | J6: 5 | K6: 1 | L6: 5 | M6: 5 | N6: 1 | O6: 4 | P6: 5 | Q6: 2 | R6: 2 | S6: 4 | T6: 4 | U6: 3 | V6: 5 | W6: 5 | X6: 5 | Z6: 动作与逐帧状态完整；非人类、无音频
A7: ViCo | B7: 系统+深研 | C7: P0 | D7: P0 | E7: A | F7: A | G7: 86 | H7: 3.07 | I7: 3.95 | J7: 5 | K7: 5 | L7: 3 | M7: 3 | N7: 5 | O7: 4 | P7: 4 | Q7: 5 | R7: 2 | S7: 3 | T7: 4 | U7: 4 | V7: 4 | W7: 5 | X7: 5 | Z7: 听者行为稀缺，规模小也高价值 ; 小而关键，正中倾听行为
A8: BEAT2 | B8: 系统+深研 | C8: P1 | D8: P1 | E8: S | F8: S | G8: 69 | H8: 2.46 | I8: 4.3 | J8: 4 | K8: 5 | L8: 5 | M8: 3 | N8: 5 | O8: 5 | P8: 5 | Q8: 5 | R8: 3 | S8: 3 | T8: 5 | U8: 3 | V8: 5 | W8: 5 | X8: 5 | Z8: 接近脸-手-身体整体协同目标 ; 数字人动作条件最实用
A9: BEDD | B9: 深研 | C9: P1 | D9: P1 | F9: A | I9: 3.87 | J9: 5 | K9: 3 | L9: 5 | M9: 4 | N9: 1 | O9: 3 | P9: 4 | Q9: 2 | R9: 3 | S9: 3 | T9: 5 | U9: 4 | V9: 5 | W9: 5 | X9: 5 | Z9: 任务成功与偏好数据强
A10: DROID | B10: 系统+深研 | C10: P1 | D10: P1 | E10: A | F10: S | G10: 69 | H10: 2.46 | I10: 4.15 | J10: 5 | K10: 3 | L10: 5 | M10: 5 | N10: 1 | O10: 4 | P10: 5 | Q10: 2 | R10: 5 | S10: 4 | T10: 5 | U10: 3 | V10: 4 | W10: 4 | X10: 5 | Y10: 系统=A；深研=S | Z10: 真实物理交互补模拟器域差 ; 动作精确、场景多，机器人域
A11: MineRL | B11: 系统+深研 | C11: P1 | D11: P1 | E11: S | F11: A | G11: 70 | H11: 2.5 | I11: 3.92 | J11: 5 | K11: 3 | L11: 5 | M11: 5 | N11: 1 | O11: 2 | P11: 5 | Q11: 2 | R11: 4 | S11: 3 | T11: 4 | U11: 4 | V11: 5 | W11: 5 | X11: 4 | Y11: 系统=S；深研=A | Z11: 少数真正对齐像素流与人类动作输入的数据 ; 动作/状态强；画质与兼容性弱
A12: TEACh | B12: 系统+深研 | C12: P1 | D12: P1 | E12: S | F12: S | G12: 68 | H12: 2.43 | I12: 4.46 | J12: 5 | K12: 5 | L12: 5 | M12: 5 | N12: 2 | O12: 3 | P12: 5 | Q12: 4 | R12: 4 | S12: 5 | T12: 4 | U12: 4 | V12: 5 | W12: 4 | X12: 5 | Z12: 多轮用户指令、纠正和任务状态 ; 对话纠错和任务执行高度适配
A13: VirtualHome | B13: 系统+深研 | C13: P1 | D13: P1 | E13: S | F13: S | G13: 95 | H13: 3.39 | I13: 4.41 | J13: 5 | K13: 4 | L13: 5 | M13: 5 | N13: 1 | O13: 3 | P13: 5 | Q13: 5 | R13: 4 | S13: 4 | T13: 5 | U13: 4 | V13: 5 | W13: 5 | X13: 5 | Z13: 比纯机器人模拟更接近NPC和人物活动 ; 显式状态极强，视觉域偏合成
A14: Ego-Exo4D | B14: 系统+深研 | C14: P2 | D14: P2 | E14: S | F14: S | G14: 87 | H14: 3.11 | I14: 4.15 | J14: 5 | K14: 5 | L14: 4 | M14: 4 | N14: 5 | O14: 5 | P14: 5 | Q14: 5 | R14: 5 | S14: 4 | T14: 3 | U14: 1 | V14: 3 | W14: 3 | X14: 5 | Z14: 跨视角世界模型与多传感器关键资产 ; 多视角强，处理成本很高
A15: RH20T | B15: 深研 | C15: P2 | D15: P2 | F15: A | I15: 3.91 | J15: 5 | K15: 3 | L15: 5 | M15: 5 | N15: 4 | O15: 4 | P15: 5 | Q15: 2 | R15: 4 | S15: 3 | T15: 4 | U15: 1 | V15: 3 | W15: 4 | X15: 5 | Z15: 音频/力/动作强，体量大
A16: AI2-THOR | B16: 系统 | D16: S | E16: S | G16: 71 | H16: 2.54 | Z16: 两周内最易构建可重放动作-状态数据
A17: ALFRED | B17: 系统+深研 | D17: S | E17: S | F17: S | G17: 71 | H17: 2.54 | I17: 4.47 | J17: 5 | K17: 4 | L17: 5 | M17: 5 | N17: 1 | O17: 3 | P17: 5 | Q17: 4 | R17: 4 | S17: 5 | T17: 5 | U17: 5 | V17: 5 | W17: 4 | X17: 5 | Z17: 结构清晰，适合Schema与状态差分验证 ; 语言-动作-状态链完整
A18: AMI Meeting Corpus | B18: 系统 | D18: S | E18: S | G18: 93 | H18: 3.32 | Z18: 轮次、重叠和backchannel仍不可替代
A19: AVSpeech | B19: 系统 | D19: S | E19: S | G19: 72 | H19: 2.57 | Z19: 音画同步、口型和说话人面部运动核心
A20: BEHAVIOR-1K/OmniGibson | B20: 系统+深研 | D20: S | E20: S | G20: 86 | H20: 3.07 | Z20: 状态监督和多步骤任务最强资产之一
A21: BridgeData V2 | B21: 系统+深研 | D21: S | E21: A | F21: S | G21: 70 | H21: 2.5 | I21: 4.15 | J21: 5 | K21: 3 | L21: 5 | M21: 5 | N21: 1 | O21: 4 | P21: 5 | Q21: 2 | R21: 4 | S21: 4 | T21: 5 | U21: 4 | V21: 4 | W21: 4 | X21: 5 | Y21: 系统=A；深研=S | Z21: 工程可用的真实动作条件数据 ; 日常操作与语言强
A22: CelebV-Text | B22: 系统 | D22: S | E22: S | G22: 71 | H22: 2.54 | Z22: 人物视频文本对齐与可控生成价值高
A23: EPIC-SOUNDS | B23: 系统+深研 | D23: S | E23: A | F23: S | G23: 68 | H23: 2.43 | I23: 4.35 | J23: 4 | K23: 5 | L23: 4 | M23: 4 | N23: 5 | O23: 4 | P23: 5 | Q23: 3 | R23: 4 | S23: 5 | T23: 5 | U23: 4 | V23: 4 | W23: 4 | X23: 5 | Y23: 系统=A；深研=S | Z23: 补足动作音效和环境声音结果 ; 与EPIC视频天然对齐
A24: HD-EPIC | B24: 深研 | D24: S | F24: S | I24: 4.39 | J24: 5 | K24: 5 | L24: 5 | M24: 5 | N24: 5 | O24: 5 | P24: 5 | Q24: 4 | R24: 4 | S24: 4 | T24: 3 | U24: 2 | V24: 4 | W24: 4 | X24: 5 | Z24: 状态/音频/3D 标注密度高
A25: MineDojo | B25: 系统 | D25: S | E25: S | G25: 71 | H25: 2.54 | Z25: 可控、可重放、可生成反事实
A26: OmniMMI | B26: 系统 | D26: S | E26: S | G26: 84 | H26: 3.0 | Z26: 流式状态、动作规划、主动响应和多轮依赖
A27: OpenVid-1M | B27: 系统 | D27: S | E27: S | G27: 55 | H27: 1.96 | Z27: 高质量通用视频回放与人物子集兼顾
A28: ResponseNet | B28: 系统 | D28: S | E28: S | G28: 91 | H28: 3.25 | Z28: 与在线听者语音+面部响应高度匹配
A29: SpeakerVid-5M | B29: 系统 | D29: S | E29: S | G29: 98 | H29: 3.5 | Z29: 截至截止日最贴近数字人双人交互目标的公开资源之一
A30: TalkingHead-1KH | B30: 系统 | D30: S | E30: S | G30: 75 | H30: 2.68 | Z30: 快速构建高质量talking-head smoke池
A31: VideoFDB | B31: 系统 | D31: S | E31: S | G31: 94 | H31: 3.36 | Z31: 目前最直接评测AV2AV全双工动态
A32: AMASS | B32: 系统 | D32: A | E32: A | G32: 56 | H32: 2.0 | Z32: 统一SMPL动作表示，身体先验核心
A33: ARCTIC | B33: 系统+深研 | D33: A | E33: A | F33: A | G33: 73 | H33: 2.61 | I33: 3.95 | J33: 5 | K33: 5 | L33: 5 | M33: 5 | N33: 1 | O33: 5 | P33: 5 | Q33: 3 | R33: 3 | S33: 3 | T33: 3 | U33: 2 | V33: 4 | W33: 3 | X33: 5 | Z33: 可动对象状态和双手接触稀缺 ; 接触与关节状态强
A34: BEAT | B34: 系统+深研 | D34: A | E34: S | F34: A | G34: 64 | H34: 2.29 | I34: 4.13 | J34: 4 | K34: 5 | L34: 5 | M34: 3 | N34: 5 | O34: 5 | P34: 5 | Q34: 5 | R34: 3 | S34: 3 | T34: 4 | U34: 3 | V34: 4 | W34: 5 | X34: 4 | Y34: 系统=S；深研=A | Z34: 语音到全身手势的核心数据 ; 动作与语音强，非真实RGB
A35: CALVIN | B35: 系统 | D35: A | E35: A | G35: 69 | H35: 2.46 | Z35: 多步任务进度和记忆验证
A36: CHiME-6 | B36: 系统 | D36: A | E36: A | G36: 73 | H36: 2.61 | Z36: 重叠语音和远场音频前端价值高
A37: CMU Panoptic | B37: 系统 | D37: A | E37: A | G37: 68 | H37: 2.43 | Z37: 多人同步多视角与3D标注稀缺
A38: DexYCB | B38: 深研 | D38: A | F38: A | I38: 3.58 | J38: 4 | K38: 5 | L38: 4 | M38: 4 | N38: 1 | O38: 5 | P38: 4 | Q38: 4 | R38: 3 | S38: 3 | T38: 3 | U38: 2 | V38: 3 | W38: 3 | X38: 5 | Z38: 抓取精确但任务窄
A39: EgoCom | B39: 系统 | D39: A | E39: A | G39: 88 | H39: 3.14 | Z39: 真实社交对话和长时听说视角
A40: EgoExoLearn | B40: 深研 | D40: A | F40: A | I40: 3.99 | J40: 5 | K40: 5 | L40: 4 | M40: 4 | N40: 3 | O40: 4 | P40: 5 | Q40: 4 | R40: 5 | S40: 3 | T40: 3 | U40: 2 | V40: 4 | W40: 4 | X40: 5 | Z40: reference video/跨视角强
...

Sheet 03_首期数据方案
A1: 第一阶段数据构建方案
A2: 推荐：118小时论文导向平衡；两周先交付40小时smoke set。
A4: 方案层级 | B4: 方案 | C4: 数据模块 | D4: 数据来源/构成 | E4: 目标时长(h) | F4: 比例 | G4: 音频 | H4: 动作监督 | I4: 状态监督 | J4: 存储建议 | K4: 人工抽检 | L4: 工程难点/研究问题 | M4: 状态/首轮任务
A5: 首批118小时拆分 | B5: 论文导向平衡 | C5: MIRA Rocket Science | D5: MIRA Rocket Science | E5: 20 | F5: =E5/SUM($E$5:$E$13) | L5: 动作/状态/多实体 | M5: 立即下载test
A6: 首批118小时拆分 | B6: 论文导向平衡 | C6: EPIC-KITCHENS-100 | D6: EPIC-KITCHENS-100 | E6: 18 | F6: =E6/SUM($E$5:$E$13) | L6: 人-物状态变化/音效 | M6: 公开
A7: 首批118小时拆分 | B7: 论文导向平衡 | C7: MineRL + BEDD | D7: MineRL + BEDD | E7: 20 | F7: =E7/SUM($E$5:$E$13) | L7: 第一人称键鼠/任务 | M7: 公开
A8: 首批118小时拆分 | B8: 论文导向平衡 | C8: Ego4D精选 | D8: Ego4D精选 | E8: 8 | F8: =E8/SUM($E$5:$E$13) | L8: 真实HOI/社交/记忆 | M8: 立即申请
A9: 首批118小时拆分 | B9: 论文导向平衡 | C9: ViCo + EasyCom | D9: ViCo + EasyCom | E9: 4 | F9: =E9/SUM($E$5:$E$13) | L9: 倾听/多人AV | M9: 小而关键
A10: 首批118小时拆分 | B10: 论文导向平衡 | C10: VirtualHome + TEACh | D10: VirtualHome + TEACh | E10: 8 | F10: =E10/SUM($E$5:$E$13) | L10: 显式状态/对话纠错 | M10: 自行生成
A11: 首批118小时拆分 | B11: 论文导向平衡 | C11: DROID精选 | D11: DROID精选 | E11: 8 | F11: =E11/SUM($E$5:$E$13) | L11: 精确动作-结果 | M11: 公开
A12: 首批118小时拆分 | B12: 论文导向平衡 | C12: Assembly101精选 | D12: Assembly101精选 | E12: 8 | F12: =E12/SUM($E$5:$E$13) | L12: 装配/错误纠正 | M12: 公开
A13: 首批118小时拆分 | B13: 论文导向平衡 | C13: 扩展补充 | D13: HoloAssist + HD-EPIC + HOI4D + BEAT2 | E13: 24 | F13: =E13/SUM($E$5:$E$13) | G13: 是/部分 | H13: 语义/连续动作 | I13: 中强 | J13: 0.3–1.5TB | K13: 15% | L13: 全双工、精细手物状态、数字人动作与真实场景扩展 | M13: 按许可与 pilot 结果动态分配
A14: 模块级方案 | B14: 最低成本快速 Demo | C14: 游戏动作 | D14: MIRA20 + MineRL/BEDD24 | E14: 44 | F14: 52% | G14: 少量/无 | H14: 强 | I14: 强 | J14: 0.3–0.8TB ; 4–6TB | K14: 10% | L14: 格式统一/域偏差 ; 统一action token能否驱动反馈
A15: 模块级方案 | B15: 最低成本快速 Demo | C15: 真实人-物 | D15: EPIC18 + Ego4D10 | E15: 28 | F15: 33% | G15: 是 | H15: 语义动作 | I15: 中强 | J15: 0.3–0.8TB ; 4–6TB | K15: 15% | L15: 动作边界/状态抽取 ; state-change caption是否优于普通caption
A16: 模块级方案 | B16: 最低成本快速 Demo | C16: 数字人/对话 | D16: ViCo2 + EasyCom2 | E16: 4 | F16: 5% | G16: 是 | H16: 非语言反馈 | I16: 对话状态 | J16: <0.1TB ; 4–6TB | K16: 20% | L16: speaker/listener对齐 ; 倾听反馈能否作为独立action
A17: 模块级方案 | B17: 最低成本快速 Demo | C17: 合成状态 | D17: VirtualHome/TEACh8 | E17: 8 | F17: 10% | G17: 可选 | H17: 强 | I17: 最强 | J17: 0.1–0.3TB ; 4–6TB | K17: 5% | L17: 自动渲染 ; 显式before/after是否提高结果正确性
A18: 模块级方案 | B18: 最低成本快速 Demo | C18: 合计 | E18: 84 | F18: 100% | J18: 0.8–2TB ; 4–6TB
A19: 模块级方案 | B19: 论文导向平衡 | C19: 游戏动作 | D19: MIRA25 + MineRL/BEDD20 | E19: 45 | F19: 38% | G19: 少量 | H19: 强 | I19: 强 | J19: 0.4–1TB ; 8–12TB | K19: 10% | L19: 多域动作映射 ; 统一人-人/人-物/人-环境schema
A20: 模块级方案 | B20: 论文导向平衡 | C20: 真实人-物/环境 | D20: EPIC/HD-EPIC25 + Ego4D10 + Assembly10 | E20: 45 | F20: 38% | G20: 大部分 | H20: 语义动作 | I20: 强 | J20: 1–2.5TB ; 8–12TB | K20: 15% | L20: 许可/长视频/多视角 ; 结构化状态+视觉特征联合条件
A21: 模块级方案 | B21: 论文导向平衡 | C21: 精确动作 | D21: DROID/HOI4D12 | E21: 12 | F21: 10% | G21: 少量 | H21: 连续动作 | I21: 强 | J21: 0.3–1TB ; 8–12TB | K21: 12% | L21: 机器人动作映射 ; Outcome-aware/action-aware微调
A22: 模块级方案 | B22: 论文导向平衡 | C22: 数字人/全双工 | D22: ViCo/EasyCom/BEAT2 6 | E22: 6 | F22: 5% | G22: 是 | H22: 姿态/对话 | I22: 中 | J22: <0.3TB ; 8–12TB | K22: 20% | L22: motion渲染/AV对齐 ; 倾听行为与NPC反馈统一
A23: 模块级方案 | B23: 论文导向平衡 | C23: 合成状态 | D23: VirtualHome/TEACh/BEHAVIOR10 | E23: 10 | F23: 9% | G23: 可选 | H23: 强 | I23: 最强 | J23: 0.2–0.6TB ; 8–12TB | K23: 5% | L23: 仿真管线 ; 显式Entity/Object/Scene Memory
A24: 模块级方案 | B24: 论文导向平衡 | C24: 合计 | E24: 118 | F24: 100% | J24: 2–5TB ; 8–12TB
A25: 模块级方案 | B25: 效果优先 | C25: 游戏/多人 | D25: MIRA35 + PLAICraft20或自采 | E25: 55 | F25: 37% | G25: 部分 | H25: 强 | I25: 强 | J25: 1–3TB ; 15–25TB | K25: 10% | L25: 自采/隐私 ; 多NPC/全双工/长期状态
A26: 模块级方案 | B26: 效果优先 | C26: 真实人本 | D26: EPIC/HD30 + Ego4D/Exo15 + Assembly15 | E26: 60 | F26: 41% | G26: 大部分 | H26: 语义动作 | I26: 强 | J26: 3–6TB ; 15–25TB | K26: 15% | L26: 多视角/许可 ; 视觉表现与真实泛化
A27: 模块级方案 | B27: 效果优先 | C27: 精确物理 | D27: DROID/RH20T/HOI4D15 | E27: 15 | F27: 10% | G27: 部分 | H27: 连续动作 | I27: 强 | J27: 0.5–2TB ; 15–25TB | K27: 12% | L27: 传感器异构 ; 接触与结果一致性
A28: 模块级方案 | B28: 效果优先 | C28: 数字人/AV | D28: UDIVA/ViCo/EasyCom/BEAT2 8 | E28: 8 | F28: 5% | G28: 是 | H28: 姿态/对话 | I28: 中 | J28: 0.2–1TB ; 15–25TB | K28: 25% | L28: 访问/隐私/分离 ; 可打断与倾听反馈
A29: 模块级方案 | B29: 效果优先 | C29: 合成状态 | D29: VirtualHome/TEACh/BEHAVIOR10 | E29: 10 | F29: 7% | G29: 可选 | H29: 强 | I29: 最强 | J29: 0.2–0.8TB ; 15–25TB | K29: 5% | L29: 仿真稳定性 ; 长期记忆与反事实状态
A30: 模块级方案 | B30: 效果优先 | C30: 合计 | E30: 148 | F30: 100% | J30: 5–10TB ; 15–25TB
A31: 宏观扩展方案 | B31: 40小时 Smoke | C31: 总体 | D31: OpenVid 4h; TalkingHead 5h; AVSpeech 7h; BEAT/动作4h; EasyCom/AMI 4h; EPIC/HOI 5h; AI2-THOR/ALFRED 5h; MineRL 3h; 自采全双工3h | F31: Replay10%; 人物25%; 视听27.5%; 自然交互22.5%; 条件/流式15% | J31: 120–250GB ; 0.5–1TB ; 1–2TB | M31: DataLoader、统一Schema、sync条件、动作token、流式切片
A32: 宏观扩展方案 | B32: 100–150小时 平衡集 | C32: 总体 | D32: Replay 25–35h; 人物35–40h; 视听25–30h; HHI/HOI 20–25h; 游戏/模拟15–20h; 全双工/记忆10–15h | F32: Replay25%; 人物30%; 视听20%; 交互15%; 条件/全双工/记忆10% | J32: 0.5–1.5TB ; 2–4TB ; 4–8TB | M32: 5B继续训练+能力adapter；阶段式与混合课程对比

Sheet 04_训练阶段映射
A1: 训练阶段映射与课程建议
A2: 广覆盖体系负责能力分层，执行深研体系负责每阶段的可操作数据组合。
A4: 阶段 | B4: 核心能力 | C4: 推荐数据 | D4: 建议比例 | E4: 关键策略
A5: Stage 0 | B5: 通用视频、场景、物体/摄像机运动、replay | C5: OpenVid-1M; HD-VILA-100M; Panda-70M小子集; MiraData; Kinetics人物子集 | D5: 总batch 20–35% replay | E5: 固定高质量回放池；许可allowlist；低质大数据不得压倒专项数据
A6: Stage 1 | B6: 人脸、身份、上半身、全身、手、多人物 | C6: CelebV-HQ; CelebV-Text; TalkingHead-1KH; VFHQ; Kinetics人物子集; CMU Panoptic; Motion-X | D6: 脸30%；上半身20%；全身25%；手10%；多人/多视角15% | E6: 主体尺度分桶；自然访谈高于演员情绪；保留人物与场景共存
A7: Stage 2 | B7: 口型、表情、视线、手势、听者反应 | C7: AVSpeech; LRS2/3; BEAT/BEAT2; TalkSHOW; EasyCom; NoXi; ResponseNet; SpeakerVid-5M | D7: 说话40%；整体手势25%；听者/双人20%；情绪15% | E7: 先做sync门槛；演员情绪降权；speaker/listener双轨
A8: Stage 3 | B8: 人-人、人-物、人-环境、接触与状态变化 | C8: Ego4D; Ego-Exo4D; EPIC-KITCHENS; Assembly101; HOI4D; H2O; ARCTIC; InterHuman; VirtualHome | D8: 真实RGB 65–75%；模拟/3D动作25–35% | E8: 保留动作前-接触-动作后；episode抽样；失败/纠正不过滤
A9: Stage 4 | B9: 语言/动作/键鼠条件、NPC响应、世界变化 | C9: MineRL; MineDojo; AI2-THOR; VirtualHome; TEACh; ALFRED; BEHAVIOR-1K; DROID | D9: 可重放模拟50%；游戏20%；真实机器人20%；自采10% | E9: raw/semantic action分开；状态前后差分；同初态多分支
A10: Stage 5 | B10: 重叠、打断、backchannel、低延迟 | C10: EasyCom; AMI; CHiME-6; NoXi; MultiMediate; ResponseNet; SpeakerVid-5M; VideoFDB仅评测 | D10: 公开真实40%；自采40%；合成/重构20% | E10: 双流时间轴、事件窗口、floor state和latency
A11: Stage 6 | B11: 身份/实体/任务状态、场景重访、out-of-sight | C11: Ego4D; Ego-Exo4D; Assembly101; MineRL; MineDojo; BEHAVIOR-1K; OmniMMI/VideoFDB/EgoSchema仅评测 | D11: 长真实40%；可重放模拟40%；自采记忆脚本20% | E11: episode/实体分组切分；benchmark黑名单；递增长上下文

Sheet 05_下载申请清单
A1: 下载、注册与申请执行清单
A2: 先完成最小 pilot 与许可快照，再决定是否扩量；A/B/C 三类必须分别管理。
A4: 优先级 | B4: 数据 | C4: 访问等级 | D4: 立即动作 | E4: 最小验证集 | F4: 首期目标 | G4: 预计空间 | H4: 官方入口 | I4: 许可动作 | J4: 完成标准 | K4: 日程 | L4: 执行状态 | M4: 负责人 | N4: 最后更新 | O4: 备注
A5: P0 | B5: HoloAssist | C5: A 直接下载 | D5: 下载 1–2 个 session | E5: 1–5 个样本 | F5: 2–5h | G5: 20–100GB | H5: https://holoassist.github.io/ | I5: 保存许可快照 | J5: RGB/Depth/Gaze/Audio/动作标注可对齐 | K5: Day1–2 | L5: 未开始 | N5: 2026-07-11 | O5: 新增最高优先级遗漏
A6: P0 | B6: MIRA Rocket Science | C6: B 登录并接受条款 | D6: HF 登录并接受条款，下载 test | E6: test 109GB | F6: 20–35h | G6: 0.1–0.3TB | H6: https://huggingface.co/datasets/kyutai/rocket-science | I6: 保存许可与 Epic 条款 | J6: frames/actions/events/physics 可对齐 | K6: Day1–2 | L6: 未开始 | N6: 2026-07-11 | O6: 先 test，不直接拉取全量
A7: P0 | B7: EPIC-KITCHENS-100 | C7: A 直接下载 | D7: 下载 annotations + 2–5 个原始视频 | E7: 约20GB pilot | F7: 18–30h | G7: 0.2–0.5TB | H7: https://epic-kitchens.github.io/2026 | I7: 保存 CC BY-NC 4.0 | J7: 裁切/音频/before-after 全链路 | K7: Day1–3 | L7: 未开始 | N7: 2026-07-11
A8: P0 | B8: Ego4D | C8: C 申请/审批 | D8: 签署许可并配置 CLI | E8: HOI/Social sample | F8: 8–15h | G8: 0.3–1TB | H8: https://ego4d-data.org | I8: 归档协议与凭证有效期 | J8: 审批通过并生成 manifest | K8: Day1 | L8: 未开始 | N8: 2026-07-11 | O8: 申请应最先提交
A9: P0 | B9: Assembly101 | C9: A 直接下载 | D9: 下载 1–2 个玩具、2 个视角 | E9: 1–2 玩具/2 视角 | F9: 8–12h | G9: 0.2–0.8TB | H9: https://assembly-101.github.io | I9: 保存 CC BY-NC | J9: 动作/手姿态/相机可解析 | K9: Day2–4 | L9: 未开始 | N9: 2026-07-11
A10: P0 | B10: ViCo | C10: A 直接下载 | D10: 从项目页下载全量 | E10: 95min 全量 | F10: 全量 | G10: <20GB | H10: https://project.mhzhou.com/vico | I10: 保存 research-only 许可 | J10: speaker/listener/audio 无缺失 | K10: Day1–2 | L10: 未开始 | N10: 2026-07-11 | O10: 无需联系作者
A11: P0 | B11: EasyCom | C11: A 直接下载 | D11: 从 GitHub Releases 下载 | E11: 1 session | F11: 全量约5h | G11: 0.1–0.5TB | H11: https://github.com/facebookresearch/EasyComDataset | I11: 核查并保存数据条款 | J11: 视频/阵列音频/VAD/转录可对齐 | K11: Day1–3 | L11: 未开始 | N11: 2026-07-11 | O11: 原表状态已修正
A12: P0 | B12: AgiBot World | C12: B 登录并接受条款 | D12: 登录 HF 并下载小分片 | E12: 1 个小分片 | F12: 8–15h | G12: 0.2–1TB | H12: https://huggingface.co/datasets/agibot-world/AgiBotWorld-Alpha | I12: 保存条款和版本 | J12: 视频/深度/action/proprio 可对齐 | K12: Day1–4 | L12: 未开始 | N12: 2026-07-11 | O12: 新增重要机器人数据
A13: P1 | B13: MineRL / BEDD | C13: A 直接下载/SDK | D13: 安装并读取 100 条轨迹 | E13: 100 trajectories | F13: 20–24h | G13: 0.2–1TB | H13: https://github.com/minerllabs/basalt-benchmark | I13: 核查 EULA | J13: 逐 step 动作对齐且可重放 | K13: Day2–5 | L13: 未开始 | N13: 2026-07-11
A14: P1 | B14: DROID | C14: A 直接下载/流式 | D14: 流式读取 100 episodes | E14: 100 episodes | F14: 8–12h | G14: 0.2–0.8TB | H14: https://droid-dataset.github.io | I14: 保存数据条款 | J14: 相机/action/语言/标定可解析 | K14: Day3–5 | L14: 未开始 | N14: 2026-07-11
A15: P1 | B15: TEACh / VirtualHome | C15: A 直接安装/生成 | D15: 跑通任务渲染 | E15: 10 trajectories | F15: 8–12h | G15: 0.2–0.6TB | H15: https://github.com/alexa/teach | I15: 保存代码与资产许可 | J15: 自动生成 before/action/after | K15: Day3–7 | L15: 未开始 | N15: 2026-07-11
A16: P1 | B16: RoboCasa365 | C16: A 直接安装/生成 | D16: 生成 20 条任务轨迹 | E16: 20 trajectories | F16: 8–15h | G16: 0.2–1TB | H16: https://robocasa.ai/ | I16: 保存代码/资产许可 | J16: 动作、物体状态和阶段标签完整 | K16: Day3–7 | L16: 未开始 | N16: 2026-07-11 | O16: 新增显式状态数据
A17: P1 | B17: BEAT2 | C17: A 直接下载 | D17: 下载并渲染 10 段 | E17: 10 clips | F17: 2–4h | G17: 0.1–0.4TB | H17: https://pantomatrix.github.io/BEAT2/ | I17: 保存非商业许可 | J17: 音频-网格-渲染同步 | K17: Day4–7 | L17: 未开始 | N17: 2026-07-11
A18: P1 | B18: HOT3D | C18: B 接受许可后下载 | D18: 接受许可并下载 clips | E18: 1 个 clips 子集 | F18: 2–5h | G18: 0.1–0.5TB | H18: https://facebookresearch.github.io/hot3d/ | I18: 保存 Project Aria 相关许可 | J18: 手/物体姿态/眼动/SLAM 可解析 | K18: Day2–5 | L18: 未开始 | N18: 2026-07-11 | O18: 新增精确手物状态
A19: P2 | B19: Ego-Exo4D | C19: C 申请/审批 | D19: 签署新许可 | E19: sample subset | F19: 5–10h | G19: 0.5–2TB | H19: https://ego-exo4d-data.org | I19: 归档协议 | J19: 下载目标技能子集 | K19: Day1–5 | L19: 未开始 | N19: 2026-07-11
A20: P2 | B20: RH20T | C20: A 直接下载 | D20: 下载 320×180 单配置 | E20: 1 config pilot | F20: 5–8h | G20: 0.1–0.5TB | H20: https://rh20t.github.io | I20: 核查敏感内容条款 | J20: RGB/LowDim/audio 时间对齐 | K20: Day6–10 | L20: 未开始 | N20: 2026-07-11
A21: P2 | B21: Aria ADT / AEA | C21: B Project Aria许可 | D21: 接受许可并下载最小子集 | E21: 1 个序列 | F21: 3–6h | G21: 0.1–0.5TB | H21: https://www.projectaria.com/datasets/ | I21: 保存 Aria 数据许可 | J21: 轨迹/眼动/深度/状态可解析 | K21: Day3–7 | L21: 未开始 | N21: 2026-07-11 | O21: 新增数字孪生与长时活动
A22: 观察 | B22: PLAICraft | C22: E 尚未开放 | D22: 跟踪 release / 联系作者 | E22: 无 | F22: 不计首期 | G22: 未知 | H22: https://arxiv.org/abs/2505.12707 | I22: 等待正式 license 和 URL | J22: 真正可下载后再进入计划 | K22: 持续 | L22: 暂缓 | N22: 2026-07-11

Sheet 06_Schema与Prompt
A1: 统一交互样本 Schema 与 Caption/Prompt 规则
A2: 原始日志、规则派生和VLM标注必须分层保存；VLM不得覆盖真实状态。
A4: 整合原则 | B4: 要求
A5: 身份与角色 | B5: 每个人使用track_id；跨clip身份使用identity_group_id；speaker/listener/other使用role_timeline。
A6: 动作 | B6: raw_action保存设备输入；semantic_action保存归一化语义。
A7: 结果与状态 | B7: expected_outcome来自指令/规划；state_after必须来自日志、传感器或可见证据。
A8: 切分 | B8: 保留source_id/episode_id；作品、身份、场景、任务、物体实例与采集批次不得跨split泄漏。
A9: 记忆 | B9: memory_entities[]保存持久实体、最后观测时间、belief state与置信度。
A12: 统一交互样本 Schema 与 Caption 规则
A13: 原始日志、规则派生和VLM标注分层保存；VLM不得覆盖真实状态。
A15: 字段 | B15: 类型 | C15: 必需级别 | D15: 推荐来源 | E15: VLM可生成 | F15: 人工/规则抽检 | G15: 说明
A16: sample_id | B16: string | C16: 必需 | D16: 管线生成 | E16: 否 | F16: 唯一性规则 | G16: dataset/sequence/start_ms
A17: video_path | B17: string | C17: 必需 | D17: 原始数据/裁切 | E17: 否 | F17: 文件存在性 | G17: 训练目标视频
A18: audio_path | B18: string|null | C18: 条件必需 | D18: 原始音轨 | E18: 否 | F18: AV sync | G18: 无音频写null
A19: reference_image | B19: string|null | C19: 建议必需 | D19: 动作前稳定帧 | E19: 可自动选择 | F19: 10%人工 | G19: 通常action前0.5–1.5s
A20: history_video | B20: string|null | C20: 流式必需 | D20: 同一连续序列 | E20: 否 | F20: 边界检查 | G20: 与future不重叠
A21: source_dataset | B21: string | C21: 必需 | D21: license ledger | E21: 否 | F21: 全量 | G21: 可追溯
A22: source_sequence_id | B22: string | C22: 必需 | D22: 原始metadata | E22: 否 | F22: 全量 | G22: 用于去重与split
A23: license | B23: object | C23: 必需 | D23: 许可快照 | E23: 否 | F23: 全量 | G23: name/url/version/restrictions
A24: scene_type | B24: string | C24: 必需 | D24: 原始标签/VLM | E24: 是 | F24: 10% | G24: 厨房/游戏/客厅等
A25: viewpoint | B25: enum | C25: 必需 | D25: metadata/VLM | E25: 是 | F25: 规则+抽检 | G25: ego/exo/fixed/game
A26: actors | B26: array<object> | C26: 必需 | D26: tracker+VLM | E26: 是 | F26: 20% | G26: role/track_id/bbox/visibility
... A53: 人-物物理交互 | B53: 动作前后各1–2s；手与目标物可见 | C53: 标接触开始/结束、手-物关系、位姿/容器/关节、脱手/滑落/失败 | D53: contact/hand_object/object_pose/articulation/containment/ownership/success | E53: 遮挡期间无日志证据则unknown | F53: 人-物/递交/工具 | G53: state_delta为最小变化集合

Sheet 07_流水线与质控
A1: 预处理、自动标注与质量控制
A2: source audit → download → decode → dedup → segmentation → quality gates → tracks → AV alignment → state extraction → split audit → packing
A4: 来源层 | B4: 阶段/模块 | C4: 输入 | D4: 工具/实现建议 | E4: 关键输出 | F4: 硬过滤阈值 | G4: 软评分/成本 | H4: 人工抽检 | I4: 常见失败/注意 | J4: 推荐参数/建议
A5: 广覆盖工具链 | B5: 下载/归档 | C5: URL/ID | D5: yt-dlp + aria2c + fsspec | E5: 原始媒体+来源元数据 | G5: 网络/CPU；0.2–1×实时 | I5: 遵守平台/协议；保留source hash和takedown映射
A6: 广覆盖工具链 | B6: 解码/标准化 | C6: 原视频 | D6: FFmpeg | E6: CFR视频、分离音频 | G6: NVDEC可远快于实时 | I6: 保留原始timebase；sync前不重采样
A7: 广覆盖工具链 | B7: 镜头切分 | C7: 视频 | D7: PySceneDetect / TransNetV2 | E7: shot boundaries | G7: 数十至数百fps/GPU | I7: 对话长镜头使用保守阈值
A8: 广覆盖工具链 | B8: 去重 | C8: 片段 | D8: pHash/CLIP embedding + FAISS | E8: 近重复簇 | G8: 50–300fps/GPU | I8: 源视频/作品级先分组
A9: 广覆盖工具链 | B9: 视频质量 | C9: 片段 | D9: DOVER + VMAF辅助 | E9: 质量/美学/技术分 | G9: 数十fps/GPU | I9: 质量分不能替代人物/交互人工审查
A10: 广覆盖工具链 | B10: 人物检测跟踪 | C10: RGB | D10: YOLO11/RT-DETR + ByteTrack/BoT-SORT + SAM2 | E10: person masks/tracks | G10: 20–100fps/GPU | I10: 遮挡时记录ID置信度
A11: 广覆盖工具链 | B11: 人脸/身份 | C11: 人物轨迹 | D11: SCRFD/RetinaFace + InsightFace/ArcFace | E11: face tracks/ID clusters | G11: 100–500fps/GPU | I11: 身份向量仅内部切分，不公开
A12: 广覆盖工具链 | B12: 2D姿态 | C12: 人物裁剪 | D12: DWPose / ViTPose++ | E12: body/hand/face keypoints | G12: 10–80fps/GPU | I12: 手部小像素需过滤
A13: 广覆盖工具链 | B13: 整体3D人体 | C13: RGB轨迹 | D13: SMPLer-X / 4D-Humans / WHAM | E13: SMPL-X/SMPL时序 | G13: 1–20fps/GPU | I13: 自动拟合不是GT；保留误差
A14: 广覆盖工具链 | B14: 手部3D | C14: 手部裁剪 | D14: HaMeR | E14: MANO参数 | G14: 10–50fps/GPU | I14: 接触遮挡需过滤
A15: 广覆盖工具链 | B15: 面部/表情 | C15: 脸轨迹 | D15: DECA/EMOCA/MediaPipe Face Mesh | E15: FLAME/landmarks | G15: 20–200fps/GPU | I15: 表情强度做身份归一化
A16: 广覆盖工具链 | B16: 视线 | C16: 脸/眼裁剪 | D16: Gaze360/ETH-XGaze系 | E16: gaze vector+confidence | G16: 50–200fps/GPU | I16: 侧脸眼镜低清置信度低
... A25: 广覆盖工具链 | B25: 数据打包 | C25: 媒体+标注 | D25: WebDataset/Parquet manifests | E25: 流式shards | G25: I/O为主 | I25: clip是view，episode是主实体
A26: 执行质控 | B26: 1.许可账本 | C26: URL/协议/数据卡 | D26: license_ledger.yaml + 网页/PDF快照 | E26: version/license/restrictions | F26: 无明确研究使用依据→不训练 | G26: 许可清晰度1–5 | H26: 100% | I26: 代码开源不等于数据可训练 | J26: 训练片段 ; 人-物/游戏4–8s；复杂对话8–16s；长记忆保留30–60s索引
A27: 执行质控 | B27: 2.下载校验 | C27: 分片/压缩包 | D27: aria2/rclone/hf_transfer/awscli + SHA256 | E27: 原始只读区 | F27: 校验失败/缺失→重下 | G27: 完整性 | H27: 首批100% | I27: 云盘限流/断点失败 | J27: FPS ; 首期12–16fps；动作日志保留原频率后对齐
A28: 执行质控 | B28: 3.去重 | C28: 视频/帧 | D28: 视频pHash+音频指纹+source_id | E28: duplicate_group | F28: 完全重复/重编码重复剔除 | G28: 近重复距离 | H28: 5% | I28: 多视角误判重复 | J28: 分辨率 ; 5B快速实验512×288或512×320；源视频保留原始/720p
A29: 执行质控 | B29: 4.连续性 | C29: 长视频 | D29: PySceneDetect+光流突变+音频断点 | E29: continuous_segments | F29: 交互核心区硬切→剔除 | G29: cut density | H29: 10% | I29: 快速转头误判切镜 | J29: 采样比例 ; 50% state-change；20% movement；15% dialogue/listening；10% failure/correction；5% no-op
